Workbook
Name TiposDeManutencao: Deflatores!$G$4:$G$38
Name TiposDeFuncao: Deflatores!$L$37:$L$64

Sheet Contagem
A1: Identificação da Contagem
A4: Empresa | F4: Secretaria de Estado de Planejamento e Gestão de Mato Grosso | O4: PF IFPUG | Q4: ='Funções'!L4 -> 328
A5: Aplicação | F5: COSIGNAÇÃO | O5: PF Local do EM | Q5: ='Funções'!L5 -> 328
A6: Tipo de Contagem | F6: Projeto de Desenvolvimento | O6: PF Local da FS | Q6: ='Funções'!L6 -> 290.7
A7: Nível de Detalhe | F7: Estimativa (NESMA) | O7: Tecnologia | R7: Java
A8: Projeto | F8: Revisão de Contratos Consignações | O8: Versão do Guia | R8: 4.3.1
A9: Responsável | F9: Jonathas Gomes | R9: 45797
A10: Revisor | F10: Jonathas Gomes | O10: Revisão | R10: 45869
A11: Propósito da Contagem
A12: Criar a linha de base (baseline) para o produto de software/módulo COSIGNADOS afim de propiciar o planejamento, execução e monitoramento do processo de desenvolvimento de software do referido produto. - Dar suporte à análise de qualidade e produtividade; - Estimar o custos e recursos requeridos para o desenvolvimento, melhoria e manutenção do software; - Fornecer um fator de normalização para a comparação de software; - Determinar o tamanho de um pacote de aplicação adquirido, por meio do dimensionamento funcional de todas as funções incluídas no mesmo; - Ajudar os usuários a determinar o benefício provido por um pacote de aplicação para a sua organização, por meio do dimensionamento funcional das funções que correspondam especificamente aos seus requisitos.
A16: Escopo da Contagem
A17: Contratos de Consignação ERP Seplag Cargas de dados Contagem atualizada em 31/07/2025. Inclui apenas melhorias impactadas e novas funcionalidades. Não usar como baseline.
A21: Documentação Utilizada na Análise
A22: US001 - Listar todos os contratos de consignações.docx US002 - Listagem das Consignatárias.docx US003 - Cadastro de Responsável pela Consignatária US004 - Acesso das Consignatárias.docx US005 - Resposta da Consignatária.docx US006 - Resposta do Contratante.docx US007 - Relatório da Revisão dos contratos.docx Protótipo de interface: https://app.quant-ux.com/#/share.html?h=a2aa10ahgUld478MG4WlWixuT4VbuYdz2zx05rABWkEzgUqgGb1sNm8hBVny Contagem atualizada conforme documentação disponibilizada em 31/07/2025, com a documentação ou estórias de usuário criadas e atualizadas após o dia 20/05/2025 (primeira versao da contagem).

Sheet Funções
A1: Planilha de contagem de ponto de função - Versão 2.4
A4: =Contagem!A5&" : "&Contagem!F5 -> Aplicação : COSIGNAÇÃO | B4: =Contagem!A8&" : "&Contagem!F8 -> Projeto : Revisão de Contratos Consignações | K4: PF IFPUG | L4: =SUM(H8:H809) -> 328
A5: =Contagem!A9&" : "&Contagem!F9 -> Responsável : Jonathas Gomes | B5: =Contagem!A10&" : "&Contagem!F10 -> Revisor : Jonathas Gomes | K5: PF Local do EM | L5: =SUM(K8:K809) -> 328
A6: =Contagem!A4&" : "&Contagem!F4 -> Empresa : Secretaria de Estado de Planejamento e Gestão de Mato Grosso | B6: ="Tipo da Contagem : "&Contagem!F6 -> Tipo da Contagem : Projeto de Desenvolvimento | K6: PF Local da FS | L6: =SUM(L8:L809) -> 290.7
A7: Nome da Função | B7: Tipo | C7: Manutenção | D7: TD | E7: AR/TR | F7: Complex. | G7: ctl | H7: PF IFPUG | I7: C | J7: ctl2 | K7: PF Local do EM | L7: PF Local da FS | M7: Pacote | N7: Referência | O7: Observações
F8: =IF(ISBLANK(B8),"",IF(I8="L","Baixa",IF(I8="A","Média",IF(I8="","","Alta")))) | G8: =CONCATENATE(B8,I8) | H8: =IF(ISBLANK(B8),"",IF(B8="ALI",IF(I8="L",7,IF(I8="A",10,15)),IF(B8="AIE",IF(I8="L",5,IF(I8="A",7,10)),IF(B8="SE",IF(I8="L",4,IF(I8="A",5,7)),IF(OR(B8="EE",B8="CE"),IF(I8="L",3,IF(I8="A",4,6)),0))))) | I8: =IF(OR(ISBLANK(D8),ISBLANK(E8)),IF(OR(B8="ALI",B8="AIE"),"L",IF(OR(B8="EE",B8="SE",B8="CE"),"A","")),IF(B8="EE",IF(E8>=3,IF(D8>=5,"H","A"),IF(E8>=2,IF(D8>=16,"H",IF(D8<=4,"L","A")),IF(D8<=15,"L","A"))),IF(OR(B8="SE",B8="CE"),IF(E8>=4,IF(D8>=6,"H","A"),IF(E8>=2,IF(D8>=20,"H",IF(D8<=5,"L","A")),IF(D8<=19,"L","A"))),IF(OR(B8="ALI",B8="AIE"),IF(E8>=6,IF(D8>=20,"H","A"),IF(E8>=2,IF(D8>=51,"H",IF(D8<=19,"L","A")),IF(D8<=50,"L","A"))),"")))) | J8: =CONCATENATE(B8,C8) | K8: =IF(OR(H8="",H8=0),L8,H8) | L8: =IF(NOT(ISERROR(VLOOKUP(B8,Deflatores!G$42:H$64,2,FALSE))),VLOOKUP(B8,Deflatores!G$42:H$64,2,FALSE),IF(OR(ISBLANK(C8),ISBLANK(B8)),"",VLOOKUP(C8,Deflatores!G$4:H$38,2,FALSE)*H8+VLOOKUP(C8,Deflatores!G$4:I$38,3,FALSE)))
A9: US001 - Listar todos os contratos de consignações | F9: =IF(ISBLANK(B9),"",IF(I9="L","Baixa",IF(I9="A","Média",IF(I9="","","Alta")))) | G9: =CONCATENATE(B9,I9) | H9: =IF(ISBLANK(B9),"",IF(B9="ALI",IF(I9="L",7,IF(I9="A",10,15)),IF(B9="AIE",IF(I9="L",5,IF(I9="A",7,10)),IF(B9="SE",IF(I9="L",4,IF(I9="A",5,7)),IF(OR(B9="EE",B9="CE"),IF(I9="L",3,IF(I9="A",4,6)),0))))) | I9: =IF(OR(ISBLANK(D9),ISBLANK(E9)),IF(OR(B9="ALI",B9="AIE"),"L",IF(OR(B9="EE",B9="SE",B9="CE"),"A","")),IF(B9="EE",IF(E9>=3,IF(D9>=5,"H","A"),IF(E9>=2,IF(D9>=16,"H",IF(D9<=4,"L","A")),IF(D9<=15,"L","A"))),IF(OR(B9="SE",B9="CE"),IF(E9>=4,IF(D9>=6,"H","A"),IF(E9>=2,IF(D9>=20,"H",IF(D9<=5,"L","A")),IF(D9<=19,"L","A"))),IF(OR(B9="ALI",B9="AIE"),IF(E9>=6,IF(D9>=20,"H","A"),IF(E9>=2,IF(D9>=51,"H",IF(D9<=19,"L","A")),IF(D9<=50,"L","A"))),"")))) | J9: =CONCATENATE(B9,C9) | K9: =IF(OR(H9="",H9=0),L9,H9) | L9: =IF(NOT(ISERROR(VLOOKUP(B9,Deflatores!G$42:H$64,2,FALSE))),VLOOKUP(B9,Deflatores!G$42:H$64,2,FALSE),IF(OR(ISBLANK(C9),ISBLANK(B9)),"",VLOOKUP(C9,Deflatores!G$4:H$38,2,FALSE)*H9+VLOOKUP(C9,Deflatores!G$4:I$38,3,FALSE)))
A10: Contratos - Revisão - Salvar (Reconheço/Não Reconheço) | B10: EE | C10: A50 | F10: =IF(ISBLANK(B10),"",IF(I10="L","Baixa",IF(I10="A","Média",IF(I10="","","Alta")))) -> Média | G10: =CONCATENATE(B10,I10) -> EEA | H10: =IF(ISBLANK(B10),"",IF(B10="ALI",IF(I10="L",7,IF(I10="A",10,15)),IF(B10="AIE",IF(I10="L",5,IF(I10="A",7,10)),IF(B10="SE",IF(I10="L",4,IF(I10="A",5,7)),IF(OR(B10="EE",B10="CE"),IF(I10="L",3,IF(I10="A",4,6)),0))))) -> 4 | I10: =IF(OR(ISBLANK(D10),ISBLANK(E10)),IF(OR(B10="ALI",B10="AIE"),"L",IF(OR(B10="EE",B10="SE",B10="CE"),"A","")),IF(B10="EE",IF(E10>=3,IF(D10>=5,"H","A"),IF(E10>=2,IF(D10>=16,"H",IF(D10<=4,"L","A")),IF(D10<=15,"L","A"))),IF(OR(B10="SE",B10="CE"),IF(E10>=4,IF(D10>=6,"H","A"),IF(E10>=2,IF(D10>=20,"H",IF(D10<=5,"L","A")),IF(D10<=19,"L","A"))),IF(OR(B10="ALI",B10="AIE"),IF(E10>=6,IF(D10>=20,"H","A"),IF(E10>=2,IF(D10>=51,"H",IF(D10<=19,"L","A")),IF(D10<=50,"L","A"))),"")))) -> A | J10: =CONCATENATE(B10,C10) -> EEA50 | K10: =IF(OR(H10="",H10=0),L10,H10) -> 4 | L10: =IF(NOT(ISERROR(VLOOKUP(B10,Deflatores!G$42:H$64,2,FALSE))),VLOOKUP(B10,Deflatores!G$42:H$64,2,FALSE),IF(OR(ISBLANK(C10),ISBLANK(B10)),"",VLOOKUP(C10,Deflatores!G$4:H$38,2,FALSE)*H10+VLOOKUP(C10,Deflatores!G$4:I$38,3,FALSE))) -> 2 | O10: Alterado campo para obrigatório.
A11: Mensagem de Passo a Passo | B11: CE | C11: COS | F11: =IF(ISBLANK(B11),"",IF(I11="L","Baixa",IF(I11="A","Média",IF(I11="","","Alta")))) -> Média | G11: =CONCATENATE(B11,I11) -> CEA | H11: =IF(ISBLANK(B11),"",IF(B11="ALI",IF(I11="L",7,IF(I11="A",10,15)),IF(B11="AIE",IF(I11="L",5,IF(I11="A",7,10)),IF(B11="SE",IF(I11="L",4,IF(I11="A",5,7)),IF(OR(B11="EE",B11="CE"),IF(I11="L",3,IF(I11="A",4,6)),0))))) -> 4 | I11: =IF(OR(ISBLANK(D11),ISBLANK(E11)),IF(OR(B11="ALI",B11="AIE"),"L",IF(OR(B11="EE",B11="SE",B11="CE"),"A","")),IF(B11="EE",IF(E11>=3,IF(D11>=5,"H","A"),IF(E11>=2,IF(D11>=16,"H",IF(D11<=4,"L","A")),IF(D11<=15,"L","A"))),IF(OR(B11="SE",B11="CE"),IF(E11>=4,IF(D11>=6,"H","A"),IF(E11>=2,IF(D11>=20,"H",IF(D11<=5,"L","A")),IF(D11<=19,"L","A"))),IF(OR(B11="ALI",B11="AIE"),IF(E11>=6,IF(D11>=20,"H","A"),IF(E11>=2,IF(D11>=51,"H",IF(D11<=19,"L","A")),IF(D11<=50,"L","A"))),"")))) -> A | J11: =CONCATENATE(B11,C11) -> CECOS | K11: =IF(OR(H11="",H11=0),L11,H11) -> 4 | L11: =IF(NOT(ISERROR(VLOOKUP(B11,Deflatores!G$42:H$64,2,FALSE))),VLOOKUP(B11,Deflatores!G$42:H$64,2,FALSE),IF(OR(ISBLANK(C11),ISBLANK(B11)),"",VLOOKUP(C11,Deflatores!G$4:H$38,2,FALSE)*H11+VLOOKUP(C11,Deflatores!G$4:I$38,3,FALSE))) -> 0.6 | O11: Inclusão de mensagem: cosmética.
A12: Mensagem Declaração para Revisão de Contratos | B12: CE | C12: COS | F12: =IF(ISBLANK(B12),"",IF(I12="L","Baixa",IF(I12="A","Média",IF(I12="","","Alta")))) -> Média | G12: =CONCATENATE(B12,I12) -> CEA | H12: =IF(ISBLANK(B12),"",IF(B12="ALI",IF(I12="L",7,IF(I12="A",10,15)),IF(B12="AIE",IF(I12="L",5,IF(I12="A",7,10)),IF(B12="SE",IF(I12="L",4,IF(I12="A",5,7)),IF(OR(B12="EE",B12="CE"),IF(I12="L",3,IF(I12="A",4,6)),0))))) -> 4 | I12: =IF(OR(ISBLANK(D12),ISBLANK(E12)),IF(OR(B12="ALI",B12="AIE"),"L",IF(OR(B12="EE",B12="SE",B12="CE"),"A","")),IF(B12="EE",IF(E12>=3,IF(D12>=5,"H","A"),IF(E12>=2,IF(D12>=16,"H",IF(D12<=4,"L","A")),IF(D12<=15,"L","A"))),IF(OR(B12="SE",B12="CE"),IF(E12>=4,IF(D12>=6,"H","A"),IF(E12>=2,IF(D12>=20,"H",IF(D12<=5,"L","A")),IF(D12<=19,"L","A"))),IF(OR(B12="ALI",B12="AIE"),IF(E12>=6,IF(D12>=20,"H","A"),IF(E12>=2,IF(D12>=51,"H",IF(D12<=19,"L","A")),IF(D12<=50,"L","A"))),"")))) -> A | J12: =CONCATENATE(B12,C12) -> CECOS | K12: =IF(OR(H12="",H12=0),L12,H12) -> 4 | L12: =IF(NOT(ISERROR(VLOOKUP(B12,Deflatores!G$42:H$64,2,FALSE))),VLOOKUP(B12,Deflatores!G$42:H$64,2,FALSE),IF(OR(ISBLANK(C12),ISBLANK(B12)),"",VLOOKUP(C12,Deflatores!G$4:H$38,2,FALSE)*H12+VLOOKUP(C12,Deflatores!G$4:I$38,3,FALSE))) -> 0.6 | O12: Inclusão de mensagem: cosmética.
F13: =IF(ISBLANK(B13),"",IF(I13="L","Baixa",IF(I13="A","Média",IF(I13="","","Alta")))) | G13: =CONCATENATE(B13,I13) | H13: =IF(ISBLANK(B13),"",IF(B13="ALI",IF(I13="L",7,IF(I13="A",10,15)),IF(B13="AIE",IF(I13="L",5,IF(I13="A",7,10)),IF(B13="SE",IF(I13="L",4,IF(I13="A",5,7)),IF(OR(B13="EE",B13="CE"),IF(I13="L",3,IF(I13="A",4,6)),0))))) | I13: =IF(OR(ISBLANK(D13),ISBLANK(E13)),IF(OR(B13="ALI",B13="AIE"),"L",IF(OR(B13="EE",B13="SE",B13="CE"),"A","")),IF(B13="EE",IF(E13>=3,IF(D13>=5,"H","A"),IF(E13>=2,IF(D13>=16,"H",IF(D13<=4,"L","A")),IF(D13<=15,"L","A"))),IF(OR(B13="SE",B13="CE"),IF(E13>=4,IF(D13>=6,"H","A"),IF(E13>=2,IF(D13>=20,"H",IF(D13<=5,"L","A")),IF(D13<=19,"L","A"))),IF(OR(B13="ALI",B13="AIE"),IF(E13>=6,IF(D13>=20,"H","A"),IF(E13>=2,IF(D13>=51,"H",IF(D13<=19,"L","A")),IF(D13<=50,"L","A"))),"")))) | J13: =CONCATENATE(B13,C13) | K13: =IF(OR(H13="",H13=0),L13,H13) | L13: =IF(NOT(ISERROR(VLOOKUP(B13,Deflatores!G$42:H$64,2,FALSE))),VLOOKUP(B13,Deflatores!G$42:H$64,2,FALSE),IF(OR(ISBLANK(C13),ISBLANK(B13)),"",VLOOKUP(C13,Deflatores!G$4:H$38,2,FALSE)*H13+VLOOKUP(C13,Deflatores!G$4:I$38,3,FALSE)))
F14: =IF(ISBLANK(B14),"",IF(I14="L","Baixa",IF(I14="A","Média",IF(I14="","","Alta")))) | G14: =CONCATENATE(B14,I14) | H14: =IF(ISBLANK(B14),"",IF(B14="ALI",IF(I14="L",7,IF(I14="A",10,15)),IF(B14="AIE",IF(I14="L",5,IF(I14="A",7,10)),IF(B14="SE",IF(I14="L",4,IF(I14="A",5,7)),IF(OR(B14="EE",B14="CE"),IF(I14="L",3,IF(I14="A",4,6)),0))))) | I14: =IF(OR(ISBLANK(D14),ISBLANK(E14)),IF(OR(B14="ALI",B14="AIE"),"L",IF(OR(B14="EE",B14="SE",B14="CE"),"A","")),IF(B14="EE",IF(E14>=3,IF(D14>=5,"H","A"),IF(E14>=2,IF(D14>=16,"H",IF(D14<=4,"L","A")),IF(D14<=15,"L","A"))),IF(OR(B14="SE",B14="CE"),IF(E14>=4,IF(D14>=6,"H","A"),IF(E14>=2,IF(D14>=20,"H",IF(D14<=5,"L","A")),IF(D14<=19,"L","A"))),IF(OR(B14="ALI",B14="AIE"),IF(E14>=6,IF(D14>=20,"H","A"),IF(E14>=2,IF(D14>=51,"H",IF(D14<=19,"L","A")),IF(D14<=50,"L","A"))),"")))) | J14: =CONCATENATE(B14,C14) | K14: =IF(OR(H14="",H14=0),L14,H14) | L14: =IF(NOT(ISERROR(VLOOKUP(B14,Deflatores!G$42:H$64,2,FALSE))),VLOOKUP(B14,Deflatores!G$42:H$64,2,FALSE),IF(OR(ISBLANK(C14),ISBLANK(B14)),"",VLOOKUP(C14,Deflatores!G$4:H$38,2,FALSE)*H14+VLOOKUP(C14,Deflatores!G$4:I$38,3,FALSE)))
F15: =IF(ISBLANK(B15),"",IF(I15="L","Baixa",IF(I15="A","Média",IF(I15="","","Alta")))) | G15: =CONCATENATE(B15,I15) | H15: =IF(ISBLANK(B15),"",IF(B15="ALI",IF(I15="L",7,IF(I15="A",10,15)),IF(B15="AIE",IF(I15="L",5,IF(I15="A",7,10)),IF(B15="SE",IF(I15="L",4,IF(I15="A",5,7)),IF(OR(B15="EE",B15="CE"),IF(I15="L",3,IF(I15="A",4,6)),0))))) | I15: =IF(OR(ISBLANK(D15),ISBLANK(E15)),IF(OR(B15="ALI",B15="AIE"),"L",IF(OR(B15="EE",B15="SE",B15="CE"),"A","")),IF(B15="EE",IF(E15>=3,IF(D15>=5,"H","A"),IF(E15>=2,IF(D15>=16,"H",IF(D15<=4,"L","A")),IF(D15<=15,"L","A"))),IF(OR(B15="SE",B15="CE"),IF(E15>=4,IF(D15>=6,"H","A"),IF(E15>=2,IF(D15>=20,"H",IF(D15<=5,"L","A")),IF(D15<=19,"L","A"))),IF(OR(B15="ALI",B15="AIE"),IF(E15>=6,IF(D15>=20,"H","A"),IF(E15>=2,IF(D15>=51,"H",IF(D15<=19,"L","A")),IF(D15<=50,"L","A"))),"")))) | J15: =CONCATENATE(B15,C15) | K15: =IF(OR(H15="",H15=0),L15,H15) | L15: =IF(NOT(ISERROR(VLOOKUP(B15,Deflatores!G$42:H$64,2,FALSE))),VLOOKUP(B15,Deflatores!G$42:H$64,2,FALSE),IF(OR(ISBLANK(C15),ISBLANK(B15)),"",VLOOKUP(C15,Deflatores!G$4:H$38,2,FALSE)*H15+VLOOKUP(C15,Deflatores!G$4:I$38,3,FALSE)))
A16: US002 - Listagem das Consignatárias | F16: =IF(ISBLANK(B16),"",IF(I16="L","Baixa",IF(I16="A","Média",IF(I16="","","Alta")))) | G16: =CONCATENATE(B16,I16) | H16: =IF(ISBLANK(B16),"",IF(B16="ALI",IF(I16="L",7,IF(I16="A",10,15)),IF(B16="AIE",IF(I16="L",5,IF(I16="A",7,10)),IF(B16="SE",IF(I16="L",4,IF(I16="A",5,7)),IF(OR(B16="EE",B16="CE"),IF(I16="L",3,IF(I16="A",4,6)),0))))) | I16: =IF(OR(ISBLANK(D16),ISBLANK(E16)),IF(OR(B16="ALI",B16="AIE"),"L",IF(OR(B16="EE",B16="SE",B16="CE"),"A","")),IF(B16="EE",IF(E16>=3,IF(D16>=5,"H","A"),IF(E16>=2,IF(D16>=16,"H",IF(D16<=4,"L","A")),IF(D16<=15,"L","A"))),IF(OR(B16="SE",B16="CE"),IF(E16>=4,IF(D16>=6,"H","A"),IF(E16>=2,IF(D16>=20,"H",IF(D16<=5,"L","A")),IF(D16<=19,"L","A"))),IF(OR(B16="ALI",B16="AIE"),IF(E16>=6,IF(D16>=20,"H","A"),IF(E16>=2,IF(D16>=51,"H",IF(D16<=19,"L","A")),IF(D16<=50,"L","A"))),"")))) | J16: =CONCATENATE(B16,C16) | K16: =IF(OR(H16="",H16=0),L16,H16) | L16: =IF(NOT(ISERROR(VLOOKUP(B16,Deflatores!G$42:H$64,2,FALSE))),VLOOKUP(B16,Deflatores!G$42:H$64,2,FALSE),IF(OR(ISBLANK(C16),ISBLANK(B16)),"",VLOOKUP(C16,Deflatores!G$4:H$38,2,FALSE)*H16+VLOOKUP(C16,Deflatores!G$4:I$38,3,FALSE)))
F17: =IF(ISBLANK(B17),"",IF(I17="L","Baixa",IF(I17="A","Média",IF(I17="","","Alta")))) | G17: =CONCATENATE(B17,I17) | H17: =IF(ISBLANK(B17),"",IF(B17="ALI",IF(I17="L",7,IF(I17="A",10,15)),IF(B17="AIE",IF(I17="L",5,IF(I17="A",7,10)),IF(B17="SE",IF(I17="L",4,IF(I17="A",5,7)),IF(OR(B17="EE",B17="CE"),IF(I17="L",3,IF(I17="A",4,6)),0))))) | I17: =IF(OR(ISBLANK(D17),ISBLANK(E17)),IF(OR(B17="ALI",B17="AIE"),"L",IF(OR(B17="EE",B17="SE",B17="CE"),"A","")),IF(B17="EE",IF(E17>=3,IF(D17>=5,"H","A"),IF(E17>=2,IF(D17>=16,"H",IF(D17<=4,"L","A")),IF(D17<=15,"L","A"))),IF(OR(B17="SE",B17="CE"),IF(E17>=4,IF(D17>=6,"H","A"),IF(E17>=2,IF(D17>=20,"H",IF(D17<=5,"L","A")),IF(D17<=19,"L","A"))),IF(OR(B17="ALI",B17="AIE"),IF(E17>=6,IF(D17>=20,"H","A"),IF(E17>=2,IF(D17>=51,"H",IF(D17<=19,"L","A")),IF(D17<=50,"L","A"))),"")))) | J17: =CONCATENATE(B17,C17) | K17: =IF(OR(H17="",H17=0),L17,H17) | L17: =IF(NOT(ISERROR(VLOOKUP(B17,Deflatores!G$42:H$64,2,FALSE))),VLOOKUP(B17,Deflatores!G$42:H$64,2,FALSE),IF(OR(ISBLANK(C17),ISBLANK(B17)),"",VLOOKUP(C17,Deflatores!G$4:H$38,2,FALSE)*H17+VLOOKUP(C17,Deflatores!G$4:I$38,3,FALSE)))
A18: Cadastros de Consignatárias | B18: ALI | C18: A50 | D18: 3 | E18: 1 | F18: =IF(ISBLANK(B18),"",IF(I18="L","Baixa",IF(I18="A","Média",IF(I18="","","Alta")))) -> Baixa | G18: =CONCATENATE(B18,I18) -> ALIL | H18: =IF(ISBLANK(B18),"",IF(B18="ALI",IF(I18="L",7,IF(I18="A",10,15)),IF(B18="AIE",IF(I18="L",5,IF(I18="A",7,10)),IF(B18="SE",IF(I18="L",4,IF(I18="A",5,7)),IF(OR(B18="EE",B18="CE"),IF(I18="L",3,IF(I18="A",4,6)),0))))) -> 7 | I18: =IF(OR(ISBLANK(D18),ISBLANK(E18)),IF(OR(B18="ALI",B18="AIE"),"L",IF(OR(B18="EE",B18="SE",B18="CE"),"A","")),IF(B18="EE",IF(E18>=3,IF(D18>=5,"H","A"),IF(E18>=2,IF(D18>=16,"H",IF(D18<=4,"L","A")),IF(D18<=15,"L","A"))),IF(OR(B18="SE",B18="CE"),IF(E18>=4,IF(D18>=6,"H","A"),IF(E18>=2,IF(D18>=20,"H",IF(D18<=5,"L","A")),IF(D18<=19,"L","A"))),IF(OR(B18="ALI",B18="AIE"),IF(E18>=6,IF(D18>=20,"H","A"),IF(E18>=2,IF(D18>=51,"H",IF(D18<=19,"L","A")),IF(D18<=50,"L","A"))),"")))) -> L | J18: =CONCATENATE(B18,C18) -> ALIA50 | K18: =IF(OR(H18="",H18=0),L18,H18) -> 7 | L18: =IF(NOT(ISERROR(VLOOKUP(B18,Deflatores!G$42:H$64,2,FALSE))),VLOOKUP(B18,Deflatores!G$42:H$64,2,FALSE),IF(OR(ISBLANK(C18),ISBLANK(B18)),"",VLOOKUP(C18,Deflatores!G$4:H$38,2,FALSE)*H18+VLOOKUP(C18,Deflatores!G$4:I$38,3,FALSE))) -> 3.5 | O18: Criação de campo Prioridade de Atendimento.
A19: Cadastros de Consignatárias - Listagem | B19: CE | C19: A50 | D19: 3 | E19: 2 | F19: =IF(ISBLANK(B19),"",IF(I19="L","Baixa",IF(I19="A","Média",IF(I19="","","Alta")))) -> Baixa | G19: =CONCATENATE(B19,I19) -> CEL | H19: =IF(ISBLANK(B19),"",IF(B19="ALI",IF(I19="L",7,IF(I19="A",10,15)),IF(B19="AIE",IF(I19="L",5,IF(I19="A",7,10)),IF(B19="SE",IF(I19="L",4,IF(I19="A",5,7)),IF(OR(B19="EE",B19="CE"),IF(I19="L",3,IF(I19="A",4,6)),0))))) -> 3 | I19: =IF(OR(ISBLANK(D19),ISBLANK(E19)),IF(OR(B19="ALI",B19="AIE"),"L",IF(OR(B19="EE",B19="SE",B19="CE"),"A","")),IF(B19="EE",IF(E19>=3,IF(D19>=5,"H","A"),IF(E19>=2,IF(D19>=16,"H",IF(D19<=4,"L","A")),IF(D19<=15,"L","A"))),IF(OR(B19="SE",B19="CE"),IF(E19>=4,IF(D19>=6,"H","A"),IF(E19>=2,IF(D19>=20,"H",IF(D19<=5,"L","A")),IF(D19<=19,"L","A"))),IF(OR(B19="ALI",B19="AIE"),IF(E19>=6,IF(D19>=20,"H","A"),IF(E19>=2,IF(D19>=51,"H",IF(D19<=19,"L","A")),IF(D19<=50,"L","A"))),"")))) -> L | J19: =CONCATENATE(B19,C19) -> CEA50 | K19: =IF(OR(H19="",H19=0),L19,H19) -> 3 | L19: =IF(NOT(ISERROR(VLOOKUP(B19,Deflatores!G$42:H$64,2,FALSE))),VLOOKUP(B19,Deflatores!G$42:H$64,2,FALSE),IF(OR(ISBLANK(C19),ISBLANK(B19)),"",VLOOKUP(C19,Deflatores!G$4:H$38,2,FALSE)*H19+VLOOKUP(C19,Deflatores!G$4:I$38,3,FALSE))) -> 1.5 | O19: Criação de campo Prioridade de Atendimento.
A20: Cadastros de Consignatárias - Visualizar | F20: =IF(ISBLANK(B20),"",IF(I20="L","Baixa",IF(I20="A","Média",IF(I20="","","Alta")))) | G20: =CONCATENATE(B20,I20) | H20: =IF(ISBLANK(B20),"",IF(B20="ALI",IF(I20="L",7,IF(I20="A",10,15)),IF(B20="AIE",IF(I20="L",5,IF(I20="A",7,10)),IF(B20="SE",IF(I20="L",4,IF(I20="A",5,7)),IF(OR(B20="EE",B20="CE"),IF(I20="L",3,IF(I20="A",4,6)),0))))) | I20: =IF(OR(ISBLANK(D20),ISBLANK(E20)),IF(OR(B20="ALI",B20="AIE"),"L",IF(OR(B20="EE",B20="SE",B20="CE"),"A","")),IF(B20="EE",IF(E20>=3,IF(D20>=5,"H","A"),IF(E20>=2,IF(D20>=16,"H",IF(D20<=4,"L","A")),IF(D20<=15,"L","A"))),IF(OR(B20="SE",B20="CE"),IF(E20>=4,IF(D20>=6,"H","A"),IF(E20>=2,IF(D20>=20,"H",IF(D20<=5,"L","A")),IF(D20<=19,"L","A"))),IF(OR(B20="ALI",B20="AIE"),IF(E20>=6,IF(D20>=20,"H","A"),IF(E20>=2,IF(D20>=51,"H",IF(D20<=19,"L","A")),IF(D20<=50,"L","A"))),"")))) | J20: =CONCATENATE(B20,C20) | K20: =IF(OR(H20="",H20=0),L20,H20) | L20: =IF(NOT(ISERROR(VLOOKUP(B20,Deflatores!G$42:H$64,2,FALSE))),VLOOKUP(B20,Deflatores!G$42:H$64,2,FALSE),IF(OR(ISBLANK(C20),ISBLANK(B20)),"",VLOOKUP(C20,Deflatores!G$4:H$38,2,FALSE)*H20+VLOOKUP(C20,Deflatores!G$4:I$38,3,FALSE))) | O20: US003.
A21: Cadastros de Consignatárias - Adicionar | F21: =IF(ISBLANK(B21),"",IF(I21="L","Baixa",IF(I21="A","Média",IF(I21="","","Alta")))) | G21: =CONCATENATE(B21,I21) | H21: =IF(ISBLANK(B21),"",IF(B21="ALI",IF(I21="L",7,IF(I21="A",10,15)),IF(B21="AIE",IF(I21="L",5,IF(I21="A",7,10)),IF(B21="SE",IF(I21="L",4,IF(I21="A",5,7)),IF(OR(B21="EE",B21="CE"),IF(I21="L",3,IF(I21="A",4,6)),0))))) | I21: =IF(OR(ISBLANK(D21),ISBLANK(E21)),IF(OR(B21="ALI",B21="AIE"),"L",IF(OR(B21="EE",B21="SE",B21="CE"),"A","")),IF(B21="EE",IF(E21>=3,IF(D21>=5,"H","A"),IF(E21>=2,IF(D21>=16,"H",IF(D21<=4,"L","A")),IF(D21<=15,"L","A"))),IF(OR(B21="SE",B21="CE"),IF(E21>=4,IF(D21>=6,"H","A"),IF(E21>=2,IF(D21>=20,"H",IF(D21<=5,"L","A")),IF(D21<=19,"L","A"))),IF(OR(B21="ALI",B21="AIE"),IF(E21>=6,IF(D21>=20,"H","A"),IF(E21>=2,IF(D21>=51,"H",IF(D21<=19,"L","A")),IF(D21<=50,"L","A"))),"")))) | J21: =CONCATENATE(B21,C21) | K21: =IF(OR(H21="",H21=0),L21,H21) | L21: =IF(NOT(ISERROR(VLOOKUP(B21,Deflatores!G$42:H$64,2,FALSE))),VLOOKUP(B21,Deflatores!G$42:H$64,2,FALSE),IF(OR(ISBLANK(C21),ISBLANK(B21)),"",VLOOKUP(C21,Deflatores!G$4:H$38,2,FALSE)*H21+VLOOKUP(C21,Deflatores!G$4:I$38,3,FALSE))) | O21: US003.
F22: =IF(ISBLANK(B22),"",IF(I22="L","Baixa",IF(I22="A","Média",IF(I22="","","Alta")))) | G22: =CONCATENATE(B22,I22) | H22: =IF(ISBLANK(B22),"",IF(B22="ALI",IF(I22="L",7,IF(I22="A",10,15)),IF(B22="AIE",IF(I22="L",5,IF(I22="A",7,10)),IF(B22="SE",IF(I22="L",4,IF(I22="A",5,7)),IF(OR(B22="EE",B22="CE"),IF(I22="L",3,IF(I22="A",4,6)),0))))) | I22: =IF(OR(ISBLANK(D22),ISBLANK(E22)),IF(OR(B22="ALI",B22="AIE"),"L",IF(OR(B22="EE",B22="SE",B22="CE"),"A","")),IF(B22="EE",IF(E22>=3,IF(D22>=5,"H","A"),IF(E22>=2,IF(D22>=16,"H",IF(D22<=4,"L","A")),IF(D22<=15,"L","A"))),IF(OR(B22="SE",B22="CE"),IF(E22>=4,IF(D22>=6,"H","A"),IF(E22>=2,IF(D22>=20,"H",IF(D22<=5,"L","A")),IF(D22<=19,"L","A"))),IF(OR(B22="ALI",B22="AIE"),IF(E22>=6,IF(D22>=20,"H","A"),IF(E22>=2,IF(D22>=51,"H",IF(D22<=19,"L","A")),IF(D22<=50,"L","A"))),"")))) | J22: =CONCATENATE(B22,C22) | K22: =IF(OR(H22="",H22=0),L22,H22) | L22: =IF(NOT(ISERROR(VLOOKUP(B22,Deflatores!G$42:H$64,2,FALSE))),VLOOKUP(B22,Deflatores!G$42:H$64,2,FALSE),IF(OR(ISBLANK(C22),ISBLANK(B22)),"",VLOOKUP(C22,Deflatores!G$4:H$38,2,FALSE)*H22+VLOOKUP(C22,Deflatores!G$4:I$38,3,FALSE)))
F23: =IF(ISBLANK(B23),"",IF(I23="L","Baixa",IF(I23="A","Média",IF(I23="","","Alta")))) | G23: =CONCATENATE(B23,I23) | H23: =IF(ISBLANK(B23),"",IF(B23="ALI",IF(I23="L",7,IF(I23="A",10,15)),IF(B23="AIE",IF(I23="L",5,IF(I23="A",7,10)),IF(B23="SE",IF(I23="L",4,IF(I23="A",5,7)),IF(OR(B23="EE",B23="CE"),IF(I23="L",3,IF(I23="A",4,6)),0))))) | I23: =IF(OR(ISBLANK(D23),ISBLANK(E23)),IF(OR(B23="ALI",B23="AIE"),"L",IF(OR(B23="EE",B23="SE",B23="CE"),"A","")),IF(B23="EE",IF(E23>=3,IF(D23>=5,"H","A"),IF(E23>=2,IF(D23>=16,"H",IF(D23<=4,"L","A")),IF(D23<=15,"L","A"))),IF(OR(B23="SE",B23="CE"),IF(E23>=4,IF(D23>=6,"H","A"),IF(E23>=2,IF(D23>=20,"H",IF(D23<=5,"L","A")),IF(D23<=19,"L","A"))),IF(OR(B23="ALI",B23="AIE"),IF(E23>=6,IF(D23>=20,"H","A"),IF(E23>=2,IF(D23>=51,"H",IF(D23<=19,"L","A")),IF(D23<=50,"L","A"))),"")))) | J23: =CONCATENATE(B23,C23) | K23: =IF(OR(H23="",H23=0),L23,H23) | L23: =IF(NOT(ISERROR(VLOOKUP(B23,Deflatores!G$42:H$64,2,FALSE))),VLOOKUP(B23,Deflatores!G$42:H$64,2,FALSE),IF(OR(ISBLANK(C23),ISBLANK(B23)),"",VLOOKUP(C23,Deflatores!G$4:H$38,2,FALSE)*H23+VLOOKUP(C23,Deflatores!G$4:I$38,3,FALSE)))
A24: US003 - Cadastro de Responsável pela Consignatária | F24: =IF(ISBLANK(B24),"",IF(I24="L","Baixa",IF(I24="A","Média",IF(I24="","","Alta")))) | G24: =CONCATENATE(B24,I24) | H24: =IF(ISBLANK(B24),"",IF(B24="ALI",IF(I24="L",7,IF(I24="A",10,15)),IF(B24="AIE",IF(I24="L",5,IF(I24="A",7,10)),IF(B24="SE",IF(I24="L",4,IF(I24="A",5,7)),IF(OR(B24="EE",B24="CE"),IF(I24="L",3,IF(I24="A",4,6)),0))))) | I24: =IF(OR(ISBLANK(D24),ISBLANK(E24)),IF(OR(B24="ALI",B24="AIE"),"L",IF(OR(B24="EE",B24="SE",B24="CE"),"A","")),IF(B24="EE",IF(E24>=3,IF(D24>=5,"H","A"),IF(E24>=2,IF(D24>=16,"H",IF(D24<=4,"L","A")),IF(D24<=15,"L","A"))),IF(OR(B24="SE",B24="CE"),IF(E24>=4,IF(D24>=6,"H","A"),IF(E24>=2,IF(D24>=20,"H",IF(D24<=5,"L","A")),IF(D24<=19,"L","A"))),IF(OR(B24="ALI",B24="AIE"),IF(E24>=6,IF(D24>=20,"H","A"),IF(E24>=2,IF(D24>=51,"H",IF(D24<=19,"L","A")),IF(D24<=50,"L","A"))),"")))) | J24: =CONCATENATE(B24,C24) | K24: =IF(OR(H24="",H24=0),L24,H24) | L24: =IF(NOT(ISERROR(VLOOKUP(B24,Deflatores!G$42:H$64,2,FALSE))),VLOOKUP(B24,Deflatores!G$42:H$64,2,FALSE),IF(OR(ISBLANK(C24),ISBLANK(B24)),"",VLOOKUP(C24,Deflatores!G$4:H$38,2,FALSE)*H24+VLOOKUP(C24,Deflatores!G$4:I$38,3,FALSE)))
F25: =IF(ISBLANK(B25),"",IF(I25="L","Baixa",IF(I25="A","Média",IF(I25="","","Alta")))) | G25: =CONCATENATE(B25,I25) | H25: =IF(ISBLANK(B25),"",IF(B25="ALI",IF(I25="L",7,IF(I25="A",10,15)),IF(B25="AIE",IF(I25="L",5,IF(I25="A",7,10)),IF(B25="SE",IF(I25="L",4,IF(I25="A",5,7)),IF(OR(B25="EE",B25="CE"),IF(I25="L",3,IF(I25="A",4,6)),0))))) | I25: =IF(OR(ISBLANK(D25),ISBLANK(E25)),IF(OR(B25="ALI",B25="AIE"),"L",IF(OR(B25="EE",B25="SE",B25="CE"),"A","")),IF(B25="EE",IF(E25>=3,IF(D25>=5,"H","A"),IF(E25>=2,IF(D25>=16,"H",IF(D25<=4,"L","A")),IF(D25<=15,"L","A"))),IF(OR(B25="SE",B25="CE"),IF(E25>=4,IF(D25>=6,"H","A"),IF(E25>=2,IF(D25>=20,"H",IF(D25<=5,"L","A")),IF(D25<=19,"L","A"))),IF(OR(B25="ALI",B25="AIE"),IF(E25>=6,IF(D25>=20,"H","A"),IF(E25>=2,IF(D25>=51,"H",IF(D25<=19,"L","A")),IF(D25<=50,"L","A"))),"")))) | J25: =CONCATENATE(B25,C25) | K25: =IF(OR(H25="",H25=0),L25,H25) | L25: =IF(NOT(ISERROR(VLOOKUP(B25,Deflatores!G$42:H$64,2,FALSE))),VLOOKUP(B25,Deflatores!G$42:H$64,2,FALSE),IF(OR(ISBLANK(C25),ISBLANK(B25)),"",VLOOKUP(C25,Deflatores!G$4:H$38,2,FALSE)*H25+VLOOKUP(C25,Deflatores!G$4:I$38,3,FALSE)))
A26: Cadastrar Responsáveis Consignatária - Listagem | B26: CE | C26: A50 | F26: =IF(ISBLANK(B26),"",IF(I26="L","Baixa",IF(I26="A","Média",IF(I26="","","Alta")))) -> Média | G26: =CONCATENATE(B26,I26) -> CEA | H26: =IF(ISBLANK(B26),"",IF(B26="ALI",IF(I26="L",7,IF(I26="A",10,15)),IF(B26="AIE",IF(I26="L",5,IF(I26="A",7,10)),IF(B26="SE",IF(I26="L",4,IF(I26="A",5,7)),IF(OR(B26="EE",B26="CE"),IF(I26="L",3,IF(I26="A",4,6)),0))))) -> 4 | I26: =IF(OR(ISBLANK(D26),ISBLANK(E26)),IF(OR(B26="ALI",B26="AIE"),"L",IF(OR(B26="EE",B26="SE",B26="CE"),"A","")),IF(B26="EE",IF(E26>=3,IF(D26>=5,"H","A"),IF(E26>=2,IF(D26>=16,"H",IF(D26<=4,"L","A")),IF(D26<=15,"L","A"))),IF(OR(B26="SE",B26="CE"),IF(E26>=4,IF(D26>=6,"H","A"),IF(E26>=2,IF(D26>=20,"H",IF(D26<=5,"L","A")),IF(D26<=19,"L","A"))),IF(OR(B26="ALI",B26="AIE"),IF(E26>=6,IF(D26>=20,"H","A"),IF(E26>=2,IF(D26>=51,"H",IF(D26<=19,"L","A")),IF(D26<=50,"L","A"))),"")))) -> A | J26: =CONCATENATE(B26,C26) -> CEA50 | K26: =IF(OR(H26="",H26=0),L26,H26) -> 4 | L26: =IF(NOT(ISERROR(VLOOKUP(B26,Deflatores!G$42:H$64,2,FALSE))),VLOOKUP(B26,Deflatores!G$42:H$64,2,FALSE),IF(OR(ISBLANK(C26),ISBLANK(B26)),"",VLOOKUP(C26,Deflatores!G$4:H$38,2,FALSE)*H26+VLOOKUP(C26,Deflatores!G$4:I$38,3,FALSE))) -> 2 | O26: Impactado pela US002 de criação de campo.
A27: Cadastrar Responsáveis Consignatária - Pesquisar para Incluir | B27: CE | C27: A50 | F27: =IF(ISBLANK(B27),"",IF(I27="L","Baixa",IF(I27="A","Média",IF(I27="","","Alta")))) -> Média | G27: =CONCATENATE(B27,I27) -> CEA | H27: =IF(ISBLANK(B27),"",IF(B27="ALI",IF(I27="L",7,IF(I27="A",10,15)),IF(B27="AIE",IF(I27="L",5,IF(I27="A",7,10)),IF(B27="SE",IF(I27="L",4,IF(I27="A",5,7)),IF(OR(B27="EE",B27="CE"),IF(I27="L",3,IF(I27="A",4,6)),0))))) -> 4 | I27: =IF(OR(ISBLANK(D27),ISBLANK(E27)),IF(OR(B27="ALI",B27="AIE"),"L",IF(OR(B27="EE",B27="SE",B27="CE"),"A","")),IF(B27="EE",IF(E27>=3,IF(D27>=5,"H","A"),IF(E27>=2,IF(D27>=16,"H",IF(D27<=4,"L","A")),IF(D27<=15,"L","A"))),IF(OR(B27="SE",B27="CE"),IF(E27>=4,IF(D27>=6,"H","A"),IF(E27>=2,IF(D27>=20,"H",IF(D27<=5,"L","A")),IF(D27<=19,"L","A"))),IF(OR(B27="ALI",B27="AIE"),IF(E27>=6,IF(D27>=20,"H","A"),IF(E27>=2,IF(D27>=51,"H",IF(D27<=19,"L","A")),IF(D27<=50,"L","A"))),"")))) -> A | J27: =CONCATENATE(B27,C27) -> CEA50 | K27: =IF(OR(H27="",H27=0),L27,H27) -> 4 | L27: =IF(NOT(ISERROR(VLOOKUP(B27,Deflatores!G$42:H$64,2,FALSE))),VLOOKUP(B27,Deflatores!G$42:H$64,2,FALSE),IF(OR(ISBLANK(C27),ISBLANK(B27)),"",VLOOKUP(C27,Deflatores!G$4:H$38,2,FALSE)*H27+VLOOKUP(C27,Deflatores!G$4:I$38,3,FALSE))) -> 2 | O27: Impactado pela US002 de criação de campo.
A28: Cadastrar Responsáveis Consignatária - Cadastrar | B28: EE | C28: A50 | F28: =IF(ISBLANK(B28),"",IF(I28="L","Baixa",IF(I28="A","Média",IF(I28="","","Alta")))) -> Média | G28: =CONCATENATE(B28,I28) -> EEA | H28: =IF(ISBLANK(B28),"",IF(B28="ALI",IF(I28="L",7,IF(I28="A",10,15)),IF(B28="AIE",IF(I28="L",5,IF(I28="A",7,10)),IF(B28="SE",IF(I28="L",4,IF(I28="A",5,7)),IF(OR(B28="EE",B28="CE"),IF(I28="L",3,IF(I28="A",4,6)),0))))) -> 4 | I28: =IF(OR(ISBLANK(D28),ISBLANK(E28)),IF(OR(B28="ALI",B28="AIE"),"L",IF(OR(B28="EE",B28="SE",B28="CE"),"A","")),IF(B28="EE",IF(E28>=3,IF(D28>=5,"H","A"),IF(E28>=2,IF(D28>=16,"H",IF(D28<=4,"L","A")),IF(D28<=15,"L","A"))),IF(OR(B28="SE",B28="CE"),IF(E28>=4,IF(D28>=6,"H","A"),IF(E28>=2,IF(D28>=20,"H",IF(D28<=5,"L","A")),IF(D28<=19,"L","A"))),IF(OR(B28="ALI",B28="AIE"),IF(E28>=6,IF(D28>=20,"H","A"),IF(E28>=2,IF(D28>=51,"H",IF(D28<=19,"L","A")),IF(D28<=50,"L","A"))),"")))) -> A | J28: =CONCATENATE(B28,C28) -> EEA50 | K28: =IF(OR(H28="",H28=0),L28,H28) -> 4 | L28: =IF(NOT(ISERROR(VLOOKUP(B28,Deflatores!G$42:H$64,2,FALSE))),VLOOKUP(B28,Deflatores!G$42:H$64,2,FALSE),IF(OR(ISBLANK(C28),ISBLANK(B28)),"",VLOOKUP(C28,Deflatores!G$4:H$38,2,FALSE)*H28+VLOOKUP(C28,Deflatores!G$4:I$38,3,FALSE))) -> 2 | O28: Impactado pela US002 de criação de campo.
A29: Cadastrar Responsáveis Consignatária - Listar Cosignatárias | B29: CE | C29: A50 | F29: =IF(ISBLANK(B29),"",IF(I29="L","Baixa",IF(I29="A","Média",IF(I29="","","Alta")))) -> Média | G29: =CONCATENATE(B29,I29) -> CEA | H29: =IF(ISBLANK(B29),"",IF(B29="ALI",IF(I29="L",7,IF(I29="A",10,15)),IF(B29="AIE",IF(I29="L",5,IF(I29="A",7,10)),IF(B29="SE",IF(I29="L",4,IF(I29="A",5,7)),IF(OR(B29="EE",B29="CE"),IF(I29="L",3,IF(I29="A",4,6)),0))))) -> 4 | I29: =IF(OR(ISBLANK(D29),ISBLANK(E29)),IF(OR(B29="ALI",B29="AIE"),"L",IF(OR(B29="EE",B29="SE",B29="CE"),"A","")),IF(B29="EE",IF(E29>=3,IF(D29>=5,"H","A"),IF(E29>=2,IF(D29>=16,"H",IF(D29<=4,"L","A")),IF(D29<=15,"L","A"))),IF(OR(B29="SE",B29="CE"),IF(E29>=4,IF(D29>=6,"H","A"),IF(E29>=2,IF(D29>=20,"H",IF(D29<=5,"L","A")),IF(D29<=19,"L","A"))),IF(OR(B29="ALI",B29="AIE"),IF(E29>=6,IF(D29>=20,"H","A"),IF(E29>=2,IF(D29>=51,"H",IF(D29<=19,"L","A")),IF(D29<=50,"L","A"))),"")))) -> A | J29: =CONCATENATE(B29,C29) -> CEA50 | K29: =IF(OR(H29="",H29=0),L29,H29) -> 4 | L29: =IF(NOT(ISERROR(VLOOKUP(B29,Deflatores!G$42:H$64,2,FALSE))),VLOOKUP(B29,Deflatores!G$42:H$64,2,FALSE),IF(OR(ISBLANK(C29),ISBLANK(B29)),"",VLOOKUP(C29,Deflatores!G$4:H$38,2,FALSE)*H29+VLOOKUP(C29,Deflatores!G$4:I$38,3,FALSE))) -> 2 | O29: Impactado pela US002 de criação de campo.
F30: =IF(ISBLANK(B30),"",IF(I30="L","Baixa",IF(I30="A","Média",IF(I30="","","Alta")))) | G30: =CONCATENATE(B30,I30) | H30: =IF(ISBLANK(B30),"",IF(B30="ALI",IF(I30="L",7,IF(I30="A",10,15)),IF(B30="AIE",IF(I30="L",5,IF(I30="A",7,10)),IF(B30="SE",IF(I30="L",4,IF(I30="A",5,7)),IF(OR(B30="EE",B30="CE"),IF(I30="L",3,IF(I30="A",4,6)),0))))) | I30: =IF(OR(ISBLANK(D30),ISBLANK(E30)),IF(OR(B30="ALI",B30="AIE"),"L",IF(OR(B30="EE",B30="SE",B30="CE"),"A","")),IF(B30="EE",IF(E30>=3,IF(D30>=5,"H","A"),IF(E30>=2,IF(D30>=16,"H",IF(D30<=4,"L","A")),IF(D30<=15,"L","A"))),IF(OR(B30="SE",B30="CE"),IF(E30>=4,IF(D30>=6,"H","A"),IF(E30>=2,IF(D30>=20,"H",IF(D30<=5,"L","A")),IF(D30<=19,"L","A"))),IF(OR(B30="ALI",B30="AIE"),IF(E30>=6,IF(D30>=20,"H","A"),IF(E30>=2,IF(D30>=51,"H",IF(D30<=19,"L","A")),IF(D30<=50,"L","A"))),"")))) | J30: =CONCATENATE(B30,C30) | K30: =IF(OR(H30="",H30=0),L30,H30) | L30: =IF(NOT(ISERROR(VLOOKUP(B30,Deflatores!G$42:H$64,2,FALSE))),VLOOKUP(B30,Deflatores!G$42:H$64,2,FALSE),IF(OR(ISBLANK(C30),ISBLANK(B30)),"",VLOOKUP(C30,Deflatores!G$4:H$38,2,FALSE)*H30+VLOOKUP(C30,Deflatores!G$4:I$38,3,FALSE))) | O30: Impactado pela US002 de criação de campo.
A31: Cadastrar Responsáveis Consignatária - Ativar/Desativar | B31: EE | C31: I | D31: 2 | E31: 2 | F31: =IF(ISBLANK(B31),"",IF(I31="L","Baixa",IF(I31="A","Média",IF(I31="","","Alta")))) -> Baixa | G31: =CONCATENATE(B31,I31) -> EEL | H31: =IF(ISBLANK(B31),"",IF(B31="ALI",IF(I31="L",7,IF(I31="A",10,15)),IF(B31="AIE",IF(I31="L",5,IF(I31="A",7,10)),IF(B31="SE",IF(I31="L",4,IF(I31="A",5,7)),IF(OR(B31="EE",B31="CE"),IF(I31="L",3,IF(I31="A",4,6)),0))))) -> 3 | I31: =IF(OR(ISBLANK(D31),ISBLANK(E31)),IF(OR(B31="ALI",B31="AIE"),"L",IF(OR(B31="EE",B31="SE",B31="CE"),"A","")),IF(B31="EE",IF(E31>=3,IF(D31>=5,"H","A"),IF(E31>=2,IF(D31>=16,"H",IF(D31<=4,"L","A")),IF(D31<=15,"L","A"))),IF(OR(B31="SE",B31="CE"),IF(E31>=4,IF(D31>=6,"H","A"),IF(E31>=2,IF(D31>=20,"H",IF(D31<=5,"L","A")),IF(D31<=19,"L","A"))),IF(OR(B31="ALI",B31="AIE"),IF(E31>=6,IF(D31>=20,"H","A"),IF(E31>=2,IF(D31>=51,"H",IF(D31<=19,"L","A")),IF(D31<=50,"L","A"))),"")))) -> L | J31: =CONCATENATE(B31,C31) -> EEI | K31: =IF(OR(H31="",H31=0),L31,H31) -> 3 | L31: =IF(NOT(ISERROR(VLOOKUP(B31,Deflatores!G$42:H$64,2,FALSE))),VLOOKUP(B31,Deflatores!G$42:H$64,2,FALSE),IF(OR(ISBLANK(C31),ISBLANK(B31)),"",VLOOKUP(C31,Deflatores!G$4:H$38,2,FALSE)*H31+VLOOKUP(C31,Deflatores!G$4:I$38,3,FALSE))) -> 3 | O31: Impactado na US 03, criação de campo.
F32: =IF(ISBLANK(B32),"",IF(I32="L","Baixa",IF(I32="A","Média",IF(I32="","","Alta")))) | G32: =CONCATENATE(B32,I32) | H32: =IF(ISBLANK(B32),"",IF(B32="ALI",IF(I32="L",7,IF(I32="A",10,15)),IF(B32="AIE",IF(I32="L",5,IF(I32="A",7,10)),IF(B32="SE",IF(I32="L",4,IF(I32="A",5,7)),IF(OR(B32="EE",B32="CE"),IF(I32="L",3,IF(I32="A",4,6)),0))))) | I32: =IF(OR(ISBLANK(D32),ISBLANK(E32)),IF(OR(B32="ALI",B32="AIE"),"L",IF(OR(B32="EE",B32="SE",B32="CE"),"A","")),IF(B32="EE",IF(E32>=3,IF(D32>=5,"H","A"),IF(E32>=2,IF(D32>=16,"H",IF(D32<=4,"L","A")),IF(D32<=15,"L","A"))),IF(OR(B32="SE",B32="CE"),IF(E32>=4,IF(D32>=6,"H","A"),IF(E32>=2,IF(D32>=20,"H",IF(D32<=5,"L","A")),IF(D32<=19,"L","A"))),IF(OR(B32="ALI",B32="AIE"),IF(E32>=6,IF(D32>=20,"H","A"),IF(E32>=2,IF(D32>=51,"H",IF(D32<=19,"L","A")),IF(D32<=50,"L","A"))),"")))) | J32: =CONCATENATE(B32,C32) | K32: =IF(OR(H32="",H32=0),L32,H32) | L32: =IF(NOT(ISERROR(VLOOKUP(B32,Deflatores!G$42:H$64,2,FALSE))),VLOOKUP(B32,Deflatores!G$42:H$64,2,FALSE),IF(OR(ISBLANK(C32),ISBLANK(B32)),"",VLOOKUP(C32,Deflatores!G$4:H$38,2,FALSE)*H32+VLOOKUP(C32,Deflatores!G$4:I$38,3,FALSE)))
A33: US004 - Acesso das Consignatárias | F33: =IF(ISBLANK(B33),"",IF(I33="L","Baixa",IF(I33="A","Média",IF(I33="","","Alta")))) | G33: =CONCATENATE(B33,I33) | H33: =IF(ISBLANK(B33),"",IF(B33="ALI",IF(I33="L",7,IF(I33="A",10,15)),IF(B33="AIE",IF(I33="L",5,IF(I33="A",7,10)),IF(B33="SE",IF(I33="L",4,IF(I33="A",5,7)),IF(OR(B33="EE",B33="CE"),IF(I33="L",3,IF(I33="A",4,6)),0))))) | I33: =IF(OR(ISBLANK(D33),ISBLANK(E33)),IF(OR(B33="ALI",B33="AIE"),"L",IF(OR(B33="EE",B33="SE",B33="CE"),"A","")),IF(B33="EE",IF(E33>=3,IF(D33>=5,"H","A"),IF(E33>=2,IF(D33>=16,"H",IF(D33<=4,"L","A")),IF(D33<=15,"L","A"))),IF(OR(B33="SE",B33="CE"),IF(E33>=4,IF(D33>=6,"H","A"),IF(E33>=2,IF(D33>=20,"H",IF(D33<=5,"L","A")),IF(D33<=19,"L","A"))),IF(OR(B33="ALI",B33="AIE"),IF(E33>=6,IF(D33>=20,"H","A"),IF(E33>=2,IF(D33>=51,"H",IF(D33<=19,"L","A")),IF(D33<=50,"L","A"))),"")))) | J33: =CONCATENATE(B33,C33) | K33: =IF(OR(H33="",H33=0),L33,H33) | L33: =IF(NOT(ISERROR(VLOOKUP(B33,Deflatores!G$42:H$64,2,FALSE))),VLOOKUP(B33,Deflatores!G$42:H$64,2,FALSE),IF(OR(ISBLANK(C33),ISBLANK(B33)),"",VLOOKUP(C33,Deflatores!G$4:H$38,2,FALSE)*H33+VLOOKUP(C33,Deflatores!G$4:I$38,3,FALSE)))
A34: Contratos Contestados | B34: ALI | C34: A50 | F34: =IF(ISBLANK(B34),"",IF(I34="L","Baixa",IF(I34="A","Média",IF(I34="","","Alta")))) -> Baixa | G34: =CONCATENATE(B34,I34) -> ALIL | H34: =IF(ISBLANK(B34),"",IF(B34="ALI",IF(I34="L",7,IF(I34="A",10,15)),IF(B34="AIE",IF(I34="L",5,IF(I34="A",7,10)),IF(B34="SE",IF(I34="L",4,IF(I34="A",5,7)),IF(OR(B34="EE",B34="CE"),IF(I34="L",3,IF(I34="A",4,6)),0))))) -> 7 | I34: =IF(OR(ISBLANK(D34),ISBLANK(E34)),IF(OR(B34="ALI",B34="AIE"),"L",IF(OR(B34="EE",B34="SE",B34="CE"),"A","")),IF(B34="EE",IF(E34>=3,IF(D34>=5,"H","A"),IF(E34>=2,IF(D34>=16,"H",IF(D34<=4,"L","A")),IF(D34<=15,"L","A"))),IF(OR(B34="SE",B34="CE"),IF(E34>=4,IF(D34>=6,"H","A"),IF(E34>=2,IF(D34>=20,"H",IF(D34<=5,"L","A")),IF(D34<=19,"L","A"))),IF(OR(B34="ALI",B34="AIE"),IF(E34>=6,IF(D34>=20,"H","A"),IF(E34>=2,IF(D34>=51,"H",IF(D34<=19,"L","A")),IF(D34<=50,"L","A"))),"")))) -> L | J34: =CONCATENATE(B34,C34) -> ALIA50 | K34: =IF(OR(H34="",H34=0),L34,H34) -> 7 | L34: =IF(NOT(ISERROR(VLOOKUP(B34,Deflatores!G$42:H$64,2,FALSE))),VLOOKUP(B34,Deflatores!G$42:H$64,2,FALSE),IF(OR(ISBLANK(C34),ISBLANK(B34)),"",VLOOKUP(C34,Deflatores!G$4:H$38,2,FALSE)*H34+VLOOKUP(C34,Deflatores!G$4:I$38,3,FALSE))) -> 3.5 | O34: Inclusão do campo Data.
A35: Contratos Contestados - Listagem | B35: CE | C35: A50 | F35: =IF(ISBLANK(B35),"",IF(I35="L","Baixa",IF(I35="A","Média",IF(I35="","","Alta")))) -> Média | G35: =CONCATENATE(B35,I35) -> CEA | H35: =IF(ISBLANK(B35),"",IF(B35="ALI",IF(I35="L",7,IF(I35="A",10,15)),IF(B35="AIE",IF(I35="L",5,IF(I35="A",7,10)),IF(B35="SE",IF(I35="L",4,IF(I35="A",5,7)),IF(OR(B35="EE",B35="CE"),IF(I35="L",3,IF(I35="A",4,6)),0))))) -> 4 | I35: =IF(OR(ISBLANK(D35),ISBLANK(E35)),IF(OR(B35="ALI",B35="AIE"),"L",IF(OR(B35="EE",B35="SE",B35="CE"),"A","")),IF(B35="EE",IF(E35>=3,IF(D35>=5,"H","A"),IF(E35>=2,IF(D35>=16,"H",IF(D35<=4,"L","A")),IF(D35<=15,"L","A"))),IF(OR(B35="SE",B35="CE"),IF(E35>=4,IF(D35>=6,"H","A"),IF(E35>=2,IF(D35>=20,"H",IF(D35<=5,"L","A")),IF(D35<=19,"L","A"))),IF(OR(B35="ALI",B35="AIE"),IF(E35>=6,IF(D35>=20,"H","A"),IF(E35>=2,IF(D35>=51,"H",IF(D35<=19,"L","A")),IF(D35<=50,"L","A"))),"")))) -> A | J35: =CONCATENATE(B35,C35) -> CEA50 | K35: =IF(OR(H35="",H35=0),L35,H35) -> 4 | L35: =IF(NOT(ISERROR(VLOOKUP(B35,Deflatores!G$42:H$64,2,FALSE))),VLOOKUP(B35,Deflatores!G$42:H$64,2,FALSE),IF(OR(ISBLANK(C35),ISBLANK(B35)),"",VLOOKUP(C35,Deflatores!G$4:H$38,2,FALSE)*H35+VLOOKUP(C35,Deflatores!G$4:I$38,3,FALSE))) -> 2 | O35: Inclusão do campo Data e ordenação.
A36: Contratos Contestados - Abrir Contrato / Listagem (consulta implícita) | B36: CE | C36: A50 | F36: =IF(ISBLANK(B36),"",IF(I36="L","Baixa",IF(I36="A","Média",IF(I36="","","Alta")))) -> Média | G36: =CONCATENATE(B36,I36) -> CEA | H36: =IF(ISBLANK(B36),"",IF(B36="ALI",IF(I36="L",7,IF(I36="A",10,15)),IF(B36="AIE",IF(I36="L",5,IF(I36="A",7,10)),IF(B36="SE",IF(I36="L",4,IF(I36="A",5,7)),IF(OR(B36="EE",B36="CE"),IF(I36="L",3,IF(I36="A",4,6)),0))))) -> 4 | I36: =IF(OR(ISBLANK(D36),ISBLANK(E36)),IF(OR(B36="ALI",B36="AIE"),"L",IF(OR(B36="EE",B36="SE",B36="CE"),"A","")),IF(B36="EE",IF(E36>=3,IF(D36>=5,"H","A"),IF(E36>=2,IF(D36>=16,"H",IF(D36<=4,"L","A")),IF(D36<=15,"L","A"))),IF(OR(B36="SE",B36="CE"),IF(E36>=4,IF(D36>=6,"H","A"),IF(E36>=2,IF(D36>=20,"H",IF(D36<=5,"L","A")),IF(D36<=19,"L","A"))),IF(OR(B36="ALI",B36="AIE"),IF(E36>=6,IF(D36>=20,"H","A"),IF(E36>=2,IF(D36>=51,"H",IF(D36<=19,"L","A")),IF(D36<=50,"L","A"))),"")))) -> A | J36: =CONCATENATE(B36,C36) -> CEA50 | K36: =IF(OR(H36="",H36=0),L36,H36) -> 4 | L36: =IF(NOT(ISERROR(VLOOKUP(B36,Deflatores!G$42:H$64,2,FALSE))),VLOOKUP(B36,Deflatores!G$42:H$64,2,FALSE),IF(OR(ISBLANK(C36),ISBLANK(B36)),"",VLOOKUP(C36,Deflatores!G$4:H$38,2,FALSE)*H36+VLOOKUP(C36,Deflatores!G$4:I$38,3,FALSE))) -> 2 | O36: Inclusão do campo Data e ordenação.
A37: Contratos Contestados - Combo-box | B37: CE | C37: A50 | F37: =IF(ISBLANK(B37),"",IF(I37="L","Baixa",IF(I37="A","Média",IF(I37="","","Alta")))) -> Média | G37: =CONCATENATE(B37,I37) -> CEA | H37: =IF(ISBLANK(B37),"",IF(B37="ALI",IF(I37="L",7,IF(I37="A",10,15)),IF(B37="AIE",IF(I37="L",5,IF(I37="A",7,10)),IF(B37="SE",IF(I37="L",4,IF(I37="A",5,7)),IF(OR(B37="EE",B37="CE"),IF(I37="L",3,IF(I37="A",4,6)),0))))) -> 4 | I37: =IF(OR(ISBLANK(D37),ISBLANK(E37)),IF(OR(B37="ALI",B37="AIE"),"L",IF(OR(B37="EE",B37="SE",B37="CE"),"A","")),IF(B37="EE",IF(E37>=3,IF(D37>=5,"H","A"),IF(E37>=2,IF(D37>=16,"H",IF(D37<=4,"L","A")),IF(D37<=15,"L","A"))),IF(OR(B37="SE",B37="CE"),IF(E37>=4,IF(D37>=6,"H","A"),IF(E37>=2,IF(D37>=20,"H",IF(D37<=5,"L","A")),IF(D37<=19,"L","A"))),IF(OR(B37="ALI",B37="AIE"),IF(E37>=6,IF(D37>=20,"H","A"),IF(E37>=2,IF(D37>=51,"H",IF(D37<=19,"L","A")),IF(D37<=50,"L","A"))),"")))) -> A | J37: =CONCATENATE(B37,C37) -> CEA50 | K37: =IF(OR(H37="",H37=0),L37,H37) -> 4 | L37: =IF(NOT(ISERROR(VLOOKUP(B37,Deflatores!G$42:H$64,2,FALSE))),VLOOKUP(B37,Deflatores!G$42:H$64,2,FALSE),IF(OR(ISBLANK(C37),ISBLANK(B37)),"",VLOOKUP(C37,Deflatores!G$4:H$38,2,FALSE)*H37+VLOOKUP(C37,Deflatores!G$4:I$38,3,FALSE))) -> 2 | O37: Inclusão do campo Data e ordenação.
A38: Contratos Contestados - Salvar e Enviar | B38: EE | C38: A50 | F38: =IF(ISBLANK(B38),"",IF(I38="L","Baixa",IF(I38="A","Média",IF(I38="","","Alta")))) -> Média | G38: =CONCATENATE(B38,I38) -> EEA | H38: =IF(ISBLANK(B38),"",IF(B38="ALI",IF(I38="L",7,IF(I38="A",10,15)),IF(B38="AIE",IF(I38="L",5,IF(I38="A",7,10)),IF(B38="SE",IF(I38="L",4,IF(I38="A",5,7)),IF(OR(B38="EE",B38="CE"),IF(I38="L",3,IF(I38="A",4,6)),0))))) -> 4 | I38: =IF(OR(ISBLANK(D38),ISBLANK(E38)),IF(OR(B38="ALI",B38="AIE"),"L",IF(OR(B38="EE",B38="SE",B38="CE"),"A","")),IF(B38="EE",IF(E38>=3,IF(D38>=5,"H","A"),IF(E38>=2,IF(D38>=16,"H",IF(D38<=4,"L","A")),IF(D38<=15,"L","A"))),IF(OR(B38="SE",B38="CE"),IF(E38>=4,IF(D38>=6,"H","A"),IF(E38>=2,IF(D38>=20,"H",IF(D38<=5,"L","A")),IF(D38<=19,"L","A"))),IF(OR(B38="ALI",B38="AIE"),IF(E38>=6,IF(D38>=20,"H","A"),IF(E38>=2,IF(D38>=51,"H",IF(D38<=19,"L","A")),IF(D38<=50,"L","A"))),"")))) -> A | J38: =CONCATENATE(B38,C38) -> EEA50 | K38: =IF(OR(H38="",H38=0),L38,H38) -> 4 | L38: =IF(NOT(ISERROR(VLOOKUP(B38,Deflatores!G$42:H$64,2,FALSE))),VLOOKUP(B38,Deflatores!G$42:H$64,2,FALSE),IF(OR(ISBLANK(C38),ISBLANK(B38)),"",VLOOKUP(C38,Deflatores!G$4:H$38,2,FALSE)*H38+VLOOKUP(C38,Deflatores!G$4:I$38,3,FALSE))) -> 2 | O38: Inclusão do campo Data e ordenação.
A39: Mensagem Declaração para Revisão de Contratos | B39: CE | C39: I | F39: =IF(ISBLANK(B39),"",IF(I39="L","Baixa",IF(I39="A","Média",IF(I39="","","Alta")))) -> Média | G39: =CONCATENATE(B39,I39) -> CEA | H39: =IF(ISBLANK(B39),"",IF(B39="ALI",IF(I39="L",7,IF(I39="A",10,15)),IF(B39="AIE",IF(I39="L",5,IF(I39="A",7,10)),IF(B39="SE",IF(I39="L",4,IF(I39="A",5,7)),IF(OR(B39="EE",B39="CE"),IF(I39="L",3,IF(I39="A",4,6)),0))))) -> 4 | I39: =IF(OR(ISBLANK(D39),ISBLANK(E39)),IF(OR(B39="ALI",B39="AIE"),"L",IF(OR(B39="EE",B39="SE",B39="CE"),"A","")),IF(B39="EE",IF(E39>=3,IF(D39>=5,"H","A"),IF(E39>=2,IF(D39>=16,"H",IF(D39<=4,"L","A")),IF(D39<=15,"L","A"))),IF(OR(B39="SE",B39="CE"),IF(E39>=4,IF(D39>=6,"H","A"),IF(E39>=2,IF(D39>=20,"H",IF(D39<=5,"L","A")),IF(D39<=19,"L","A"))),IF(OR(B39="ALI",B39="AIE"),IF(E39>=6,IF(D39>=20,"H","A"),IF(E39>=2,IF(D39>=51,"H",IF(D39<=19,"L","A")),IF(D39<=50,"L","A"))),"")))) -> A | J39: =CONCATENATE(B39,C39) -> CEI | K39: =IF(OR(H39="",H39=0),L39,H39) -> 4 | L39: =IF(NOT(ISERROR(VLOOKUP(B39,Deflatores!G$42:H$64,2,FALSE))),VLOOKUP(B39,Deflatores!G$42:H$64,2,FALSE),IF(OR(ISBLANK(C39),ISBLANK(B39)),"",VLOOKUP(C39,Deflatores!G$4:H$38,2,FALSE)*H39+VLOOKUP(C39,Deflatores!G$4:I$38,3,FALSE))) -> 4 | O39: Inclusão de mensagem do termo.
F40: =IF(ISBLANK(B40),"",IF(I40="L","Baixa",IF(I40="A","Média",IF(I40="","","Alta")))) | G40: =CONCATENATE(B40,I40) | H40: =IF(ISBLANK(B40),"",IF(B40="ALI",IF(I40="L",7,IF(I40="A",10,15)),IF(B40="AIE",IF(I40="L",5,IF(I40="A",7,10)),IF(B40="SE",IF(I40="L",4,IF(I40="A",5,7)),IF(OR(B40="EE",B40="CE"),IF(I40="L",3,IF(I40="A",4,6)),0))))) | I40: =IF(OR(ISBLANK(D40),ISBLANK(E40)),IF(OR(B40="ALI",B40="AIE"),"L",IF(OR(B40="EE",B40="SE",B40="CE"),"A","")),IF(B40="EE",IF(E40>=3,IF(D40>=5,"H","A"),IF(E40>=2,IF(D40>=16,"H",IF(D40<=4,"L","A")),IF(D40<=15,"L","A"))),IF(OR(B40="SE",B40="CE"),IF(E40>=4,IF(D40>=6,"H","A"),IF(E40>=2,IF(D40>=20,"H",IF(D40<=5,"L","A")),IF(D40<=19,"L","A"))),IF(OR(B40="ALI",B40="AIE"),IF(E40>=6,IF(D40>=20,"H","A"),IF(E40>=2,IF(D40>=51,"H",IF(D40<=19,"L","A")),IF(D40<=50,"L","A"))),"")))) | J40: =CONCATENATE(B40,C40) | K40: =IF(OR(H40="",H40=0),L40,H40) | L40: =IF(NOT(ISERROR(VLOOKUP(B40,Deflatores!G$42:H$64,2,FALSE))),VLOOKUP(B40,Deflatores!G$42:H$64,2,FALSE),IF(OR(ISBLANK(C40),ISBLANK(B40)),"",VLOOKUP(C40,Deflatores!G$4:H$38,2,FALSE)*H40+VLOOKUP(C40,Deflatores!G$4:I$38,3,FALSE)))
A41: US005 - Resposta da Consignatária | F41: =IF(ISBLANK(B41),"",IF(I41="L","Baixa",IF(I41="A","Média",IF(I41="","","Alta")))) | G41: =CONCATENATE(B41,I41) | H41: =IF(ISBLANK(B41),"",IF(B41="ALI",IF(I41="L",7,IF(I41="A",10,15)),IF(B41="AIE",IF(I41="L",5,IF(I41="A",7,10)),IF(B41="SE",IF(I41="L",4,IF(I41="A",5,7)),IF(OR(B41="EE",B41="CE"),IF(I41="L",3,IF(I41="A",4,6)),0))))) | I41: =IF(OR(ISBLANK(D41),ISBLANK(E41)),IF(OR(B41="ALI",B41="AIE"),"L",IF(OR(B41="EE",B41="SE",B41="CE"),"A","")),IF(B41="EE",IF(E41>=3,IF(D41>=5,"H","A"),IF(E41>=2,IF(D41>=16,"H",IF(D41<=4,"L","A")),IF(D41<=15,"L","A"))),IF(OR(B41="SE",B41="CE"),IF(E41>=4,IF(D41>=6,"H","A"),IF(E41>=2,IF(D41>=20,"H",IF(D41<=5,"L","A")),IF(D41<=19,"L","A"))),IF(OR(B41="ALI",B41="AIE"),IF(E41>=6,IF(D41>=20,"H","A"),IF(E41>=2,IF(D41>=51,"H",IF(D41<=19,"L","A")),IF(D41<=50,"L","A"))),"")))) | J41: =CONCATENATE(B41,C41) | K41: =IF(OR(H41="",H41=0),L41,H41) | L41: =IF(NOT(ISERROR(VLOOKUP(B41,Deflatores!G$42:H$64,2,FALSE))),VLOOKUP(B41,Deflatores!G$42:H$64,2,FALSE),IF(OR(ISBLANK(C41),ISBLANK(B41)),"",VLOOKUP(C41,Deflatores!G$4:H$38,2,FALSE)*H41+VLOOKUP(C41,Deflatores!G$4:I$38,3,FALSE)))
A42: Resposta Consignatária - Consulta Implícita | B42: CE | C42: A50 | F42: =IF(ISBLANK(B42),"",IF(I42="L","Baixa",IF(I42="A","Média",IF(I42="","","Alta")))) -> Média | G42: =CONCATENATE(B42,I42) -> CEA | H42: =IF(ISBLANK(B42),"",IF(B42="ALI",IF(I42="L",7,IF(I42="A",10,15)),IF(B42="AIE",IF(I42="L",5,IF(I42="A",7,10)),IF(B42="SE",IF(I42="L",4,IF(I42="A",5,7)),IF(OR(B42="EE",B42="CE"),IF(I42="L",3,IF(I42="A",4,6)),0))))) -> 4 | I42: =IF(OR(ISBLANK(D42),ISBLANK(E42)),IF(OR(B42="ALI",B42="AIE"),"L",IF(OR(B42="EE",B42="SE",B42="CE"),"A","")),IF(B42="EE",IF(E42>=3,IF(D42>=5,"H","A"),IF(E42>=2,IF(D42>=16,"H",IF(D42<=4,"L","A")),IF(D42<=15,"L","A"))),IF(OR(B42="SE",B42="CE"),IF(E42>=4,IF(D42>=6,"H","A"),IF(E42>=2,IF(D42>=20,"H",IF(D42<=5,"L","A")),IF(D42<=19,"L","A"))),IF(OR(B42="ALI",B42="AIE"),IF(E42>=6,IF(D42>=20,"H","A"),IF(E42>=2,IF(D42>=51,"H",IF(D42<=19,"L","A")),IF(D42<=50,"L","A"))),"")))) -> A | J42: =CONCATENATE(B42,C42) -> CEA50 | K42: =IF(OR(H42="",H42=0),L42,H42) -> 4 | L42: =IF(NOT(ISERROR(VLOOKUP(B42,Deflatores!G$42:H$64,2,FALSE))),VLOOKUP(B42,Deflatores!G$42:H$64,2,FALSE),IF(OR(ISBLANK(C42),ISBLANK(B42)),"",VLOOKUP(C42,Deflatores!G$4:H$38,2,FALSE)*H42+VLOOKUP(C42,Deflatores!G$4:I$38,3,FALSE))) -> 2
...

Sheet Deflatores
A1: Itens Não Mensuráveis
A2: Tipo de Manutenção na Função | G2: Sigla | H2: Contribuição em PF Local | J2: PF IFPUG | K2: PF Local FS
A3: Contrato | B3: Descrição | F3: Origem | H3: Percentual (%) | I3: Fixa (PF)
A4: Adicionada | B4: Inclusão | G4: I | H4: 1 | J4: =SUMIF('Funções'!$C$8:$C$809,Deflatores!G4,'Funções'!$H$8:$H$809) -> 259 | K4: =IF(H4="",COUNTIF('Funções'!C$8:C$809,G4)*I4,H4*J4) -> 259
A5: Alterada | B5: Alteração (sem conhecimento do Fator de Impacto) | F5: SISP – 4.2 Projeto de Melhoria | G5: A | H5: 0.5 | J5: =SUMIF('Funções'!$C$8:$C$809,Deflatores!G5,'Funções'!$H$8:$H$809) -> 0 | K5: =IF(H5="",COUNTIF('Funções'!C$8:C$809,G5)*I5,H5*J5) -> 0
A6: Excluída | B6: Exclusão | F6: SISP – 4.2 Projeto de Melhoria | G6: E | H6: 0.4 | J6: =SUMIF('Funções'!$C$8:$C$809,Deflatores!G6,'Funções'!$H$8:$H$809) -> 0 | K6: =IF(H6="",COUNTIF('Funções'!C$8:C$809,G6)*I6,H6*J6) -> 0
B7: Alteração (50%) de função desenvolvida ou já alterada pela empresa atual | F7: SISP – 4.2 Projeto de Melhoria | G7: A50 | H7: 0.5 | J7: =SUMIF('Funções'!$C$8:$C$809,Deflatores!G7,'Funções'!$H$8:$H$809) -> 61 | K7: =IF(H7="",COUNTIF('Funções'!C$8:C$809,G7)*I7,H7*J7) -> 30.5
B8: Alteração (75%) de função não desenv. e ainda não alterada pela empresa atual | F8: SISP – 4.2 Projeto de Melhoria | G8: A75 | H8: 0.75 | J8: =SUMIF('Funções'!$C$8:$C$809,Deflatores!G8,'Funções'!$H$8:$H$809) -> 0 | K8: =IF(H8="",COUNTIF('Funções'!C$8:C$809,G8)*I8,H8*J8) -> 0
B9: Alteração (75%+15%): o mesmo acima + redocumentar a função | F9: SISP – 4.2 Projeto de Melhoria | G9: A90 | H9: 0.9 | J9: =SUMIF('Funções'!$C$8:$C$809,Deflatores!G9,'Funções'!$H$8:$H$809) -> 0 | K9: =IF(H9="",COUNTIF('Funções'!C$8:C$809,G9)*I9,H9*J9) -> 0
B10: Migração de Dados | F10: SISP – 4.3 Projetos de Migração de Dados | G10: PMD | H10: 1 | J10: =SUMIF('Funções'!$C$8:$C$809,Deflatores!G10,'Funções'!$H$8:$H$809) -> 0 | K10: =IF(H10="",COUNTIF('Funções'!C$8:C$809,G10)*I10,H10*J10) -> 0
B11: Corretiva (sem conhecimento do Fator de Impacto) | F11: SISP – 4.4 Manutenção Corretiva | G11: COR | H11: 0.5 | J11: =SUMIF('Funções'!$C$8:$C$809,Deflatores!G11,'Funções'!$H$8:$H$809) -> 0 | K11: =IF(H11="",COUNTIF('Funções'!C$8:C$809,G11)*I11,H11*J11) -> 0
B12: Corretiva (50%) - Fora da garantia (mesma empresa) | F12: SISP – 4.4 Manutenção Corretiva | G12: COR50 | H12: 0.5 | J12: =SUMIF('Funções'!$C$8:$C$809,Deflatores!G12,'Funções'!$H$8:$H$809) -> 0 | K12: =IF(H12="",COUNTIF('Funções'!C$8:C$809,G12)*I12,H12*J12) -> 0
B13: Corretiva (75%) - Fora da garantia (outra empresa) | F13: SISP – 4.4 Manutenção Corretiva | G13: COR75 | H13: 0.75 | J13: =SUMIF('Funções'!$C$8:$C$809,Deflatores!G13,'Funções'!$H$8:$H$809) -> 0 | K13: =IF(H13="",COUNTIF('Funções'!C$8:C$809,G13)*I13,H13*J13) -> 0
B14: Corretiva (75%+15%) - Fora da garantia (outra empresa) + Redocumentação | F14: SISP – 4.4 Manutenção Corretiva | G14: COR90 | H14: 0.9 | J14: =SUMIF('Funções'!$C$8:$C$809,Deflatores!G14,'Funções'!$H$8:$H$809) -> 0 | K14: =IF(H14="",COUNTIF('Funções'!C$8:C$809,G14)*I14,H14*J14) -> 0
B15: Corretiva em Garantia | F15: SISP – 4.4 Manutenção Corretiva | G15: GAR | H15: 0 | J15: =SUMIF('Funções'!$C$8:$C$809,Deflatores!G15,'Funções'!$H$8:$H$809) -> 0 | K15: =IF(H15="",COUNTIF('Funções'!C$8:C$809,G15)*I15,H15*J15) -> 0
B16: Mudança de Plataforma - Linguagem de Programação | F16: SISP – 4.5.1 Mudança de Plataforma – Linguagem de Programação | G16: MLP | H16: 1 | J16: =SUMIF('Funções'!$C$8:$C$809,Deflatores!G16,'Funções'!$H$8:$H$809) -> 0 | K16: =IF(H16="",COUNTIF('Funções'!C$8:C$809,G16)*I16,H16*J16) -> 0
B17: Mudança de Plataforma - Banco de Dados (outro paradigma) | F17: SISP – 4.5.2 Mudança de Plataforma – Banco de Dados | G17: MBO | H17: 1 | J17: =SUMIF('Funções'!$C$8:$C$809,Deflatores!G17,'Funções'!$H$8:$H$809) -> 0 | K17: =IF(H17="",COUNTIF('Funções'!C$8:C$809,G17)*I17,H17*J17) -> 0
B18: Mudança de Plataforma - Banco de Dados (mesmo paradigma com alterações) | F18: SISP – 4.5.2 Mudança de Plataforma – Banco de Dados | G18: MBM | H18: 0.3 | J18: =SUMIF('Funções'!$C$8:$C$809,Deflatores!G18,'Funções'!$H$8:$H$809) -> 0 | K18: =IF(H18="",COUNTIF('Funções'!C$8:C$809,G18)*I18,H18*J18) -> 0
... B21: Atualização de Versão – Banco de Dados | F21: SISP – 4.6.3 Atualização de Versão – Banco de Dados | G21: ABD | H21: 0.3 | J21: =SUMIF('Funções'!$C$8:$C$809,Deflatores!G21,'Funções'!$H$8:$H$809) -> 0 | K21: =IF(H21="",COUNTIF('Funções'!C$8:C$809,G21)*I21,H21*J21) -> 0
B22: Manutenção Cosmética | F22: SISP – 4.7 Manutenção Cosmética | G22: COS | I22: 0.6 | J22: =SUMIF('Funções'!$C$8:$C$809,Deflatores!G22,'Funções'!$H$8:$H$809) -> 8 | K22: =IF(H22="",COUNTIF('Funções'!C$8:C$809,G22)*I22,H22*J22) -> 1.2
B23: Adaptação em Funcionalidades sem Alteração de Requisitos Funcionais (sem conhecimento do Fator de Impacto) | F23: SISP – 4.8 Adaptação em Funcionalidades sem Alteração de Requisitos Funcionais | G23: ARN | H23: 0.5 | J23: =SUMIF('Funções'!$C$8:$C$809,Deflatores!G23,'Funções'!$H$8:$H$809) -> 0 | K23: =IF(H23="",COUNTIF('Funções'!C$8:C$809,G23)*I23,H23*J23) -> 0
B24: Adaptação em Funcionalidades sem Alteração de Requisitos Funcionais (50%) (em função desenvolvida ou já alterada pela empresa atual) | F24: SISP – 4.8 Adaptação em Funcionalidades sem Alteração de Requisitos Funcionais | G24: ARN50 | H24: 0.5 | J24: =SUMIF('Funções'!$C$8:$C$809,Deflatores!G24,'Funções'!$H$8:$H$809) -> 0 | K24: =IF(H24="",COUNTIF('Funções'!C$8:C$809,G24)*I24,H24*J24) -> 0
B25: Adaptação em Funcionalidades sem Alteração de Requisitos Funcionais (75%) (em função não desenvolvida e ainda não alterada pela empresa atual) | F25: SISP – 4.8 Adaptação em Funcionalidades sem Alteração de Requisitos Funcionais | G25: ARN75 | H25: 0.75 | J25: =SUMIF('Funções'!$C$8:$C$809,Deflatores!G25,'Funções'!$H$8:$H$809) -> 0 | K25: =IF(H25="",COUNTIF('Funções'!C$8:C$809,G25)*I25,H25*J25) -> 0
B26: Atualização de Dados sem Consulta Prévia | F26: SISP – 4.9.1 Apuração Especial – Base de Dados | G26: ADS | H26: 1 | J26: =SUMIF('Funções'!$C$8:$C$809,Deflatores!G26,'Funções'!$H$8:$H$809) -> 0 | K26: =IF(H26="",COUNTIF('Funções'!C$8:C$809,G26)*I26,H26*J26) -> 0
B27: Consulta Prévia sem Atualização | F27: SISP – 4.9.1 Apuração Especial – Base de Dados | G27: CPA | H27: 1 | J27: =SUMIF('Funções'!$C$8:$C$809,Deflatores!G27,'Funções'!$H$8:$H$809) -> 0 | K27: =IF(H27="",COUNTIF('Funções'!C$8:C$809,G27)*I27,H27*J27) -> 0
B28: Atualização de Dados com Consulta Prévia | F28: SISP – 4.9.1 Apuração Especial – Base de Dados | G28: ADC | H28: 0.6 | J28: =SUMIF('Funções'!$C$8:$C$809,Deflatores!G28,'Funções'!$H$8:$H$809) -> 0 | K28: =IF(H28="",COUNTIF('Funções'!C$8:C$809,G28)*I28,H28*J28) -> 0
B29: Apuração Especial – Geração de Relatórios | F29: SISP – 4.9.2 Apuração Especial – Geração de Relatórios | G29: AGR | H29: 1 | J29: =SUMIF('Funções'!$C$8:$C$809,Deflatores!G29,'Funções'!$H$8:$H$809) -> 0 | K29: =IF(H29="",COUNTIF('Funções'!C$8:C$809,G29)*I29,H29*J29) -> 0
B30: Apuração Especial – Reexecução | F30: SISP – 4.9.3 Apuração Especial – Reexecução | G30: AER | H30: 0.1 | J30: =SUMIF('Funções'!$C$8:$C$809,Deflatores!G30,'Funções'!$H$8:$H$809) -> 0 | K30: =IF(H30="",COUNTIF('Funções'!C$8:C$809,G30)*I30,H30*J30) -> 0
B31: Atualização de Dados | F31: SISP – 4.10 Atualização de Dados | G31: ATD | H31: 0.1 | J31: =SUMIF('Funções'!$C$8:$C$809,Deflatores!G31,'Funções'!$H$8:$H$809) -> 0 | K31: =IF(H31="",COUNTIF('Funções'!C$8:C$809,G31)*I31,H31*J31) -> 0
B32: Manutenção de Documentação de Sistemas Legados | F32: SISP – 4.12 Manutenção de Documentação de Sistemas Legados | G32: MSL | H32: 0.25 | J32: =SUMIF('Funções'!$C$8:$C$809,Deflatores!G32,'Funções'!$H$8:$H$809) -> 0 | K32: =IF(H32="",COUNTIF('Funções'!C$8:C$809,G32)*I32,H32*J32) -> 0
B33: Verificação de Erros (Sem Documentação de Teste existente) | F33: SISP – 4.13 Verificação de Erros | G33: VES | H33: 0.2 | J33: =SUMIF('Funções'!$C$8:$C$809,Deflatores!G33,'Funções'!$H$8:$H$809) -> 0 | K33: =IF(H33="",COUNTIF('Funções'!C$8:C$809,G33)*I33,H33*J33) -> 0
B34: Verificação de Erros (Com Documentação de Teste existente) | F34: SISP – 4.13 Verificação de Erros | G34: VEC | H34: 0.15 | J34: =SUMIF('Funções'!$C$8:$C$809,Deflatores!G34,'Funções'!$H$8:$H$809) -> 0 | K34: =IF(H34="",COUNTIF('Funções'!C$8:C$809,G34)*I34,H34*J34) -> 0
... B36: Componente Interno Reusável | F36: SISP – 4.15 Componente Interno Reusável | G36: CIR | H36: 1 | J36: =SUMIF('Funções'!$C$8:$C$809,Deflatores!G36,'Funções'!$H$8:$H$809) -> 0 | K36: =IF(H36="",COUNTIF('Funções'!C$8:C$809,G36)*I36,H36*J36) -> 0
G37: . | J37: =SUMIF('Funções'!$C$8:$C$809,Deflatores!G37,'Funções'!$H$8:$H$809) -> 0 | K37: =IF(H37="",COUNTIF('Funções'!C$8:C$809,G37)*I37,H37*J37) -> 0 | L37: ALI
G38: . | J38: =SUMIF('Funções'!$C$8:$C$809,Deflatores!G38,'Funções'!$H$8:$H$809) -> 0 | K38: =IF(H38="",COUNTIF('Funções'!C$8:C$809,G38)*I38,H38*J38) -> 0 | L38: AIE
L39: EE
A40: Itens Não Mensuráveis | G40: Sigla | H40: Contribuição em PF Local | J40: Quantidade | K40: PF Local FS | L40: CE
A41: Contrato | B41: Descrição | F41: Origem | L41: SE
B42: Páginas Estáticas | F42: SISP – 4.11 Desenvolvimento, Manutenção e Publicação de Paginas Estáticas de Intranet, Internet ou Portal | G42: PAG | H42: 0.6 | J42: =COUNTIF('Funções'!B$8:B$809,G42) -> 0 | K42: =SUMIF('Funções'!B$8:B$809,$G42,'Funções'!K$8:K$809) -> 0 | L42: =""&G42 -> PAG
B43: Manutenção Cosmética (atrelada a algo não funcional) | F43: SISP – 4.7 Manutenção Cosmética | G43: COSNF | H43: 0.6 | J43: =COUNTIF('Funções'!B$8:B$809,G43) -> 0 | K43: =SUMIF('Funções'!B$8:B$809,$G43,'Funções'!K$8:K$809) -> 0 | L43: =""&G43 -> COSNF
...

Sheet Sumário 1
A1: Sumário da Contagem
A4: =Contagem!A5&" : "&Contagem!F5 -> Aplicação : COSIGNAÇÃO | F4: =Contagem!A8&" : "&Contagem!F8 -> Projeto : Revisão de Contratos Consignações
A5: =Contagem!A9&" : "&Contagem!F9 -> Responsável : Jonathas Gomes | F5: =Contagem!A10&" : "&Contagem!F10 -> Revisor : Jonathas Gomes
A6: =Contagem!A4&" : "&Contagem!F4 -> Empresa : Secretaria de Estado de Planejamento e Gestão de Mato Grosso | F6: ="Tipo de Contagem : "&Contagem!F6 -> Tipo de Contagem : Projeto de Desenvolvimento
A7: Tipo de Função | C7: Complexidade Funcional | G7: Total PF IFPUG por Complexidade | H7: % | J7: Total PF Local FS por tipo de manutenção básica | L7: %
B10: EE | C10: =COUNTIF('Funções'!G8:G809,"EEL") -> 1 | E10: Baixa | F10: x 3 | G10: =C10*3 -> 3 | J10: =Deflatores!$G$4&"=" -> I= | K10: =SUMIF('Funções'!$J$8:$J$809,"EE"&Deflatores!G4,'Funções'!$L$8:$L$809) -> 87
C11: =COUNTIF('Funções'!G8:G809,"EEA") -> 25 | E11: Média | F11: x 4 | G11: =C11*4 -> 100 | J11: =Deflatores!$G$5&"=" -> A= | K11: =SUMIF('Funções'!$J$8:$J$809,"EE"&Deflatores!G5,'Funções'!$L$8:$L$809) -> 0
C12: =COUNTIF('Funções'!G8:G809,"EEH") -> 0 | E12: Alta | F12: x 6 | G12: =C12*6 -> 0 | J12: =Deflatores!$G$6&"=" -> E= | K12: =SUMIF('Funções'!$J$8:$J$809,"EE"&Deflatores!G6,'Funções'!$L$8:$L$809) -> 0
B14: Qtd Total | C14: =SUM(C10:C12) -> 26 | F14: Total | G14: =SUM(G10:G12) -> 103 | H14: =IF($G$45<>0,G14/$G$45,"") -> 0.31402439 | K14: =SUM(K10:K13) -> 87 | L14: =IF('Sumário 2'!L11<>0,K14/'Sumário 2'!L11,"") -> 0.29927761
B17: SE | C17: =COUNTIF('Funções'!G8:G809,"SEL") -> 0 | E17: Baixa | F17: x 4 | G17: =C17*4 -> 0 | J17: =Deflatores!$G$4&"=" -> I= | K17: =SUMIF('Funções'!$J$8:$J$809,"SE"&Deflatores!$G$4,'Funções'!$L$8:$L$809) -> 5
C18: =COUNTIF('Funções'!G8:G809,"SEA") -> 1 | E18: Média | F18: x 5 | G18: =C18*5 -> 5 | J18: =Deflatores!$G$5&"=" -> A= | K18: =SUMIF('Funções'!$J$8:$J$809,"SE"&Deflatores!$G$5,'Funções'!$L$8:$L$809) -> 0
C19: =COUNTIF('Funções'!G8:G809,"SEH") -> 0 | E19: Alta | F19: x 7 | G19: =C19*7 -> 0 | J19: =Deflatores!$G$6&"=" -> E= | K19: =SUMIF('Funções'!$J$8:$J$809,"SE"&Deflatores!$G$6,'Funções'!$L$8:$L$809) -> 0
B21: Qtd Total | C21: =SUM(C17:C19) -> 1 | F21: Total | G21: =SUM(G17:G19) -> 5 | H21: =IF($G$45<>0,G21/$G$45,"") -> 0.015243902 | K21: =SUM(K17:K20) -> 5 | L21: =IF('Sumário 2'!L11<>0,K21/'Sumário 2'!L11,"") -> 0.017199862
B24: CE | C24: =COUNTIF('Funções'!G8:G809,"CEL") -> 1 | E24: Baixa | F24: x 3 | G24: =C24*3 -> 3 | J24: =Deflatores!$G$4&"=" -> I= | K24: =SUMIF('Funções'!$J$8:$J$809,"CE"&Deflatores!$G$4,'Funções'!$L$8:$L$809) -> 120
C25: =COUNTIF('Funções'!G8:G809,"CEA") -> 39 | E25: Média | F25: x 4 | G25: =C25*4 -> 156 | J25: =Deflatores!$G$5&"=" -> A= | K25: =SUMIF('Funções'!$J$8:$J$809,"CE"&Deflatores!$G$5,'Funções'!$L$8:$L$809) -> 0
C26: =COUNTIF('Funções'!G8:G809,"CEH") -> 0 | E26: Alta | F26: x 6 | G26: =C26*6 -> 0 | J26: =Deflatores!$G$6&"=" -> E= | K26: =SUMIF('Funções'!$J$8:$J$809,"CE"&Deflatores!$G$6,'Funções'!$L$8:$L$809) -> 0
B28: Qtd Total | C28: =SUM(C24:C26) -> 40 | F28: Total | G28: =SUM(G24:G26) -> 159 | H28: =IF($G$45<>0,G28/$G$45,"") -> 0.4847561 | K28: =SUM(K24:K27) -> 120 | L28: =IF('Sumário 2'!L11<>0,K28/'Sumário 2'!L11,"") -> 0.4127967
B31: ALI | C31: =COUNTIF('Funções'!G8:G809,"ALIL") -> 8 | E31: Baixa | F31: x 7 | G31: =C31*7 -> 56 | J31: =Deflatores!$G$4&"=" -> I= | K31: =SUMIF('Funções'!$J$8:$J$809,"ALI"&Deflatores!$G$4,'Funções'!$L$8:$L$809) -> 42
C32: =COUNTIF('Funções'!G8:G809,"ALIA") -> 0 | E32: Média | F32: x 10 | G32: =C32*10 -> 0 | J32: =Deflatores!$G$5&"=" -> A= | K32: =SUMIF('Funções'!$J$8:$J$809,"ALI"&Deflatores!$G$5,'Funções'!$L$8:$L$809) -> 0
C33: =COUNTIF('Funções'!G8:G809,"ALIH") -> 0 | E33: Alta | F33: x 15 | G33: =C33*15 -> 0 | J33: =Deflatores!$G$6&"=" -> E= | K33: =SUMIF('Funções'!$J$8:$J$809,"ALI"&Deflatores!$G$6,'Funções'!$L$8:$L$809) -> 0
B35: Qtd Total | C35: =SUM(C31:C33) -> 8 | F35: Total | G35: =SUM(G31:G33) -> 56 | H35: =IF($G$45<>0,G35/$G$45,"") -> 0.17073171 | K35: =SUM(K31:K34) -> 42 | L35: =IF('Sumário 2'!L11<>0,K35/'Sumário 2'!L11,"") -> 0.14447884
B38: AIE | C38: =COUNTIF('Funções'!G8:G809,"AIEL") -> 1 | E38: Baixa | F38: x 5 | G38: =C38*5 -> 5 | J38: =Deflatores!$G$4&"=" -> I= | K38: =SUMIF('Funções'!$J$8:$J$809,"AIE"&Deflatores!$G$4,'Funções'!$L$8:$L$809) -> 5
C39: =COUNTIF('Funções'!G8:G809,"AIEA") -> 0 | E39: Média | F39: x 7 | G39: =C39*7 -> 0 | J39: =Deflatores!$G$5&"=" -> A= | K39: =SUMIF('Funções'!$J$8:$J$809,"AIE"&Deflatores!$G$5,'Funções'!$L$8:$L$809) -> 0
C40: =COUNTIF('Funções'!G8:G809,"AIEH") -> 0 | E40: Alta | F40: x 10 | G40: =C40*10 -> 0 | J40: =Deflatores!$G$6&"=" -> E= | K40: =SUMIF('Funções'!$J$8:$J$809,"AIE"&Deflatores!$G$6,'Funções'!$L$8:$L$809) -> 0
B42: Qtd Total | C42: =SUM(C38:C40) -> 1 | F42: Total | G42: =SUM(G38:G40) -> 5 | H42: =IF($G$45<>0,G42/$G$45,"") -> 0.015243902 | K42: =SUM(K38:K41) -> 5 | L42: =IF('Sumário 2'!L11<>0,K42/'Sumário 2'!L11,"") -> 0.017199862
B45: Total PF não ajustados (contagem detalhada) | G45: =SUM(G14+G21+G28+G35+G42) -> 328
B46: Total PF não ajustados (contagem estimativa) | G46: =(C10+C11+C12)*4+(C17+C18+C19)*5+(C24+C25+C26)*4+(C31+C32+C33)*7+(C38+C39+C40)*5 -> 330
