Workbook
Name TiposDeManutencao: Deflatores!$G$4:$G$38
Name TiposDeFuncao: Deflatores!$L$37:$L$64
Name TiposDeFuncao: Deflatores!$L$37:$L$64
Name TiposDeManutencao: Deflatores!$G$4:$G$38

Sheet Contagem
A1: Identificação da Contagem
A4: Empresa | F4: Secretaria de Estado de Planejamento e Gestão de Mato Grosso | O4: PF IFPUG | Q4: =#REF! -> #REF!
A5: Aplicação | F5: MANOPLA | O5: PF Local do EM | Q5: =#REF! -> #REF!
A6: Tipo de Contagem | F6: Aplicação | O6: PF Local da FS | Q6: =#REF! -> #REF!
A7: Nível de Detalhe | F7: Detalhada (IFPUG) | O7: Tecnologia | R7: JAVA
A8: Projeto | F8: MANOPLA | O8: Versão do Guia | R8: 4.3.1
A9: Responsável | F9: João Cleber | O9: Criação
A10: Revisor | F10: João Cleber | O10: Revisão
A11: Propósito da Contagem
A12: Criar a linha de base (baseline) para o produto de software/módulo MANOPLA afim de propiciar o planejamento, execução e monitoramento do processo de desenvolvimento de software do referido produto. - Dar suporte à análise de qualidade e produtividade; - Estimar o custos e recursos requeridos para o desenvolvimento, melhoria e manutenção do software; - Fornecer um fator de normalização para a comparação de software; - Determinar o tamanho de um pacote de aplicação adquirido, por meio do dimensionamento funcional de todas as funções incluídas no mesmo; - Ajudar os usuários a determinar o benefício provido por um pacote de aplicação para a sua organização, por meio do dimensionamento funcional das funções que correspondam especificamente aos seus requisitos.
A16: Escopo da Contagem
A17: Pesquisa/Diagnóstico
A21: Documentação Utilizada na Análise
A22: Versão 1.8.0

Sheet SPRINT1
A1: Planilha de contagem de ponto de função - Versão 2.4
A4: =Contagem!A5&" : "&Contagem!F5 -> Aplicação : MANOPLA | B4: =Contagem!A8&" : "&Contagem!F8 -> Projeto : MANOPLA | K4: PF IFPUG | L4: =SUM(H8:H807) -> 380
A5: =Contagem!A9&" : "&Contagem!F9 -> Responsável : João Cleber | B5: =Contagem!A10&" : "&Contagem!F10 -> Revisor : João Cleber | K5: PF Local do EM | L5: =SUM(K8:K807) -> 380
A6: =Contagem!A4&" : "&Contagem!F4 -> Empresa : Secretaria de Estado de Planejamento e Gestão de Mato Grosso | B6: ="Tipo da Contagem : "&Contagem!F6 -> Tipo da Contagem : Aplicação | K6: PF Local da FS | L6: =SUM(L8:L807) -> 380
A7: Nome da Função | B7: Tipo | C7: Manutenção | D7: TD | E7: AR/TR | F7: Complex. | G7: ctl | H7: PF IFPUG | I7: C | J7: ctl2 | K7: PF Local do EM | L7: PF Local da FS | M7: Pacote | N7: Referência | O7: Observações
A8: US 001 - Manter Termo | B8: ALI | C8: I | F8: =IF(ISBLANK(B8),"",IF(I8="L","Baixa",IF(I8="A","Média",IF(I8="","","Alta")))) -> Baixa | G8: =CONCATENATE(B8,I8) -> ALIL | H8: =IF(ISBLANK(B8),"",IF(B8="ALI",IF(I8="L",7,IF(I8="A",10,15)),IF(B8="AIE",IF(I8="L",5,IF(I8="A",7,10)),IF(B8="SE",IF(I8="L",4,IF(I8="A",5,7)),IF(OR(B8="EE",B8="CE"),IF(I8="L",3,IF(I8="A",4,6)),0))))) -> 7 | I8: =IF(OR(ISBLANK(D8),ISBLANK(E8)),IF(OR(B8="ALI",B8="AIE"),"L",IF(OR(B8="EE",B8="SE",B8="CE"),"A","")),IF(B8="EE",IF(E8>=3,IF(D8>=5,"H","A"),IF(E8>=2,IF(D8>=16,"H",IF(D8<=4,"L","A")),IF(D8<=15,"L","A"))),IF(OR(B8="SE",B8="CE"),IF(E8>=4,IF(D8>=6,"H","A"),IF(E8>=2,IF(D8>=20,"H",IF(D8<=5,"L","A")),IF(D8<=19,"L","A"))),IF(OR(B8="ALI",B8="AIE"),IF(E8>=6,IF(D8>=20,"H","A"),IF(E8>=2,IF(D8>=51,"H",IF(D8<=19,"L","A")),IF(D8<=50,"L","A"))),"")))) -> L | J8: =CONCATENATE(B8,C8) -> ALII | K8: =IF(OR(H8="",H8=0),L8,H8) -> 7 | L8: =IF(NOT(ISERROR(VLOOKUP(B8,Deflatores!G$42:H$64,2,FALSE))),VLOOKUP(B8,Deflatores!G$42:H$64,2,FALSE),IF(OR(ISBLANK(C8),ISBLANK(B8)),"",VLOOKUP(C8,Deflatores!G$4:H$38,2,FALSE)*H8+VLOOKUP(C8,Deflatores!G$4:I$38,3,FALSE))) -> 7
A9: US 001 - Manter Termo - Consulta | B9: CE | C9: I | F9: =IF(ISBLANK(B9),"",IF(I9="L","Baixa",IF(I9="A","Média",IF(I9="","","Alta")))) -> Média | G9: =CONCATENATE(B9,I9) -> CEA | H9: =IF(ISBLANK(B9),"",IF(B9="ALI",IF(I9="L",7,IF(I9="A",10,15)),IF(B9="AIE",IF(I9="L",5,IF(I9="A",7,10)),IF(B9="SE",IF(I9="L",4,IF(I9="A",5,7)),IF(OR(B9="EE",B9="CE"),IF(I9="L",3,IF(I9="A",4,6)),0))))) -> 4 | I9: =IF(OR(ISBLANK(D9),ISBLANK(E9)),IF(OR(B9="ALI",B9="AIE"),"L",IF(OR(B9="EE",B9="SE",B9="CE"),"A","")),IF(B9="EE",IF(E9>=3,IF(D9>=5,"H","A"),IF(E9>=2,IF(D9>=16,"H",IF(D9<=4,"L","A")),IF(D9<=15,"L","A"))),IF(OR(B9="SE",B9="CE"),IF(E9>=4,IF(D9>=6,"H","A"),IF(E9>=2,IF(D9>=20,"H",IF(D9<=5,"L","A")),IF(D9<=19,"L","A"))),IF(OR(B9="ALI",B9="AIE"),IF(E9>=6,IF(D9>=20,"H","A"),IF(E9>=2,IF(D9>=51,"H",IF(D9<=19,"L","A")),IF(D9<=50,"L","A"))),"")))) -> A | J9: =CONCATENATE(B9,C9) -> CEI | K9: =IF(OR(H9="",H9=0),L9,H9) -> 4 | L9: =IF(NOT(ISERROR(VLOOKUP(B9,Deflatores!G$42:H$64,2,FALSE))),VLOOKUP(B9,Deflatores!G$42:H$64,2,FALSE),IF(OR(ISBLANK(C9),ISBLANK(B9)),"",VLOOKUP(C9,Deflatores!G$4:H$38,2,FALSE)*H9+VLOOKUP(C9,Deflatores!G$4:I$38,3,FALSE))) -> 4
A10: US 001 - Manter Termo - Adicionar | B10: EE | C10: I | F10: =IF(ISBLANK(B10),"",IF(I10="L","Baixa",IF(I10="A","Média",IF(I10="","","Alta")))) -> Média | G10: =CONCATENATE(B10,I10) -> EEA | H10: =IF(ISBLANK(B10),"",IF(B10="ALI",IF(I10="L",7,IF(I10="A",10,15)),IF(B10="AIE",IF(I10="L",5,IF(I10="A",7,10)),IF(B10="SE",IF(I10="L",4,IF(I10="A",5,7)),IF(OR(B10="EE",B10="CE"),IF(I10="L",3,IF(I10="A",4,6)),0))))) -> 4 | I10: =IF(OR(ISBLANK(D10),ISBLANK(E10)),IF(OR(B10="ALI",B10="AIE"),"L",IF(OR(B10="EE",B10="SE",B10="CE"),"A","")),IF(B10="EE",IF(E10>=3,IF(D10>=5,"H","A"),IF(E10>=2,IF(D10>=16,"H",IF(D10<=4,"L","A")),IF(D10<=15,"L","A"))),IF(OR(B10="SE",B10="CE"),IF(E10>=4,IF(D10>=6,"H","A"),IF(E10>=2,IF(D10>=20,"H",IF(D10<=5,"L","A")),IF(D10<=19,"L","A"))),IF(OR(B10="ALI",B10="AIE"),IF(E10>=6,IF(D10>=20,"H","A"),IF(E10>=2,IF(D10>=51,"H",IF(D10<=19,"L","A")),IF(D10<=50,"L","A"))),"")))) -> A | J10: =CONCATENATE(B10,C10) -> EEI | K10: =IF(OR(H10="",H10=0),L10,H10) -> 4 | L10: =IF(NOT(ISERROR(VLOOKUP(B10,Deflatores!G$42:H$64,2,FALSE))),VLOOKUP(B10,Deflatores!G$42:H$64,2,FALSE),IF(OR(ISBLANK(C10),ISBLANK(B10)),"",VLOOKUP(C10,Deflatores!G$4:H$38,2,FALSE)*H10+VLOOKUP(C10,Deflatores!G$4:I$38,3,FALSE))) -> 4
A11: US 001 - Manter Termo - Alterar | B11: EE | C11: I | F11: =IF(ISBLANK(B11),"",IF(I11="L","Baixa",IF(I11="A","Média",IF(I11="","","Alta")))) -> Média | G11: =CONCATENATE(B11,I11) -> EEA | H11: =IF(ISBLANK(B11),"",IF(B11="ALI",IF(I11="L",7,IF(I11="A",10,15)),IF(B11="AIE",IF(I11="L",5,IF(I11="A",7,10)),IF(B11="SE",IF(I11="L",4,IF(I11="A",5,7)),IF(OR(B11="EE",B11="CE"),IF(I11="L",3,IF(I11="A",4,6)),0))))) -> 4 | I11: =IF(OR(ISBLANK(D11),ISBLANK(E11)),IF(OR(B11="ALI",B11="AIE"),"L",IF(OR(B11="EE",B11="SE",B11="CE"),"A","")),IF(B11="EE",IF(E11>=3,IF(D11>=5,"H","A"),IF(E11>=2,IF(D11>=16,"H",IF(D11<=4,"L","A")),IF(D11<=15,"L","A"))),IF(OR(B11="SE",B11="CE"),IF(E11>=4,IF(D11>=6,"H","A"),IF(E11>=2,IF(D11>=20,"H",IF(D11<=5,"L","A")),IF(D11<=19,"L","A"))),IF(OR(B11="ALI",B11="AIE"),IF(E11>=6,IF(D11>=20,"H","A"),IF(E11>=2,IF(D11>=51,"H",IF(D11<=19,"L","A")),IF(D11<=50,"L","A"))),"")))) -> A | J11: =CONCATENATE(B11,C11) -> EEI | K11: =IF(OR(H11="",H11=0),L11,H11) -> 4 | L11: =IF(NOT(ISERROR(VLOOKUP(B11,Deflatores!G$42:H$64,2,FALSE))),VLOOKUP(B11,Deflatores!G$42:H$64,2,FALSE),IF(OR(ISBLANK(C11),ISBLANK(B11)),"",VLOOKUP(C11,Deflatores!G$4:H$38,2,FALSE)*H11+VLOOKUP(C11,Deflatores!G$4:I$38,3,FALSE))) -> 4
A12: US 001 - Manter Termo - Excluir | B12: EE | C12: I | F12: =IF(ISBLANK(B12),"",IF(I12="L","Baixa",IF(I12="A","Média",IF(I12="","","Alta")))) -> Média | G12: =CONCATENATE(B12,I12) -> EEA | H12: =IF(ISBLANK(B12),"",IF(B12="ALI",IF(I12="L",7,IF(I12="A",10,15)),IF(B12="AIE",IF(I12="L",5,IF(I12="A",7,10)),IF(B12="SE",IF(I12="L",4,IF(I12="A",5,7)),IF(OR(B12="EE",B12="CE"),IF(I12="L",3,IF(I12="A",4,6)),0))))) -> 4 | I12: =IF(OR(ISBLANK(D12),ISBLANK(E12)),IF(OR(B12="ALI",B12="AIE"),"L",IF(OR(B12="EE",B12="SE",B12="CE"),"A","")),IF(B12="EE",IF(E12>=3,IF(D12>=5,"H","A"),IF(E12>=2,IF(D12>=16,"H",IF(D12<=4,"L","A")),IF(D12<=15,"L","A"))),IF(OR(B12="SE",B12="CE"),IF(E12>=4,IF(D12>=6,"H","A"),IF(E12>=2,IF(D12>=20,"H",IF(D12<=5,"L","A")),IF(D12<=19,"L","A"))),IF(OR(B12="ALI",B12="AIE"),IF(E12>=6,IF(D12>=20,"H","A"),IF(E12>=2,IF(D12>=51,"H",IF(D12<=19,"L","A")),IF(D12<=50,"L","A"))),"")))) -> A | J12: =CONCATENATE(B12,C12) -> EEI | K12: =IF(OR(H12="",H12=0),L12,H12) -> 4 | L12: =IF(NOT(ISERROR(VLOOKUP(B12,Deflatores!G$42:H$64,2,FALSE))),VLOOKUP(B12,Deflatores!G$42:H$64,2,FALSE),IF(OR(ISBLANK(C12),ISBLANK(B12)),"",VLOOKUP(C12,Deflatores!G$4:H$38,2,FALSE)*H12+VLOOKUP(C12,Deflatores!G$4:I$38,3,FALSE))) -> 4
A13: US 001 - Manter Termo - Visualizar | B13: SE | C13: I | F13: =IF(ISBLANK(B13),"",IF(I13="L","Baixa",IF(I13="A","Média",IF(I13="","","Alta")))) -> Média | G13: =CONCATENATE(B13,I13) -> SEA | H13: =IF(ISBLANK(B13),"",IF(B13="ALI",IF(I13="L",7,IF(I13="A",10,15)),IF(B13="AIE",IF(I13="L",5,IF(I13="A",7,10)),IF(B13="SE",IF(I13="L",4,IF(I13="A",5,7)),IF(OR(B13="EE",B13="CE"),IF(I13="L",3,IF(I13="A",4,6)),0))))) -> 5 | I13: =IF(OR(ISBLANK(D13),ISBLANK(E13)),IF(OR(B13="ALI",B13="AIE"),"L",IF(OR(B13="EE",B13="SE",B13="CE"),"A","")),IF(B13="EE",IF(E13>=3,IF(D13>=5,"H","A"),IF(E13>=2,IF(D13>=16,"H",IF(D13<=4,"L","A")),IF(D13<=15,"L","A"))),IF(OR(B13="SE",B13="CE"),IF(E13>=4,IF(D13>=6,"H","A"),IF(E13>=2,IF(D13>=20,"H",IF(D13<=5,"L","A")),IF(D13<=19,"L","A"))),IF(OR(B13="ALI",B13="AIE"),IF(E13>=6,IF(D13>=20,"H","A"),IF(E13>=2,IF(D13>=51,"H",IF(D13<=19,"L","A")),IF(D13<=50,"L","A"))),"")))) -> A | J13: =CONCATENATE(B13,C13) -> SEI | K13: =IF(OR(H13="",H13=0),L13,H13) -> 5 | L13: =IF(NOT(ISERROR(VLOOKUP(B13,Deflatores!G$42:H$64,2,FALSE))),VLOOKUP(B13,Deflatores!G$42:H$64,2,FALSE),IF(OR(ISBLANK(C13),ISBLANK(B13)),"",VLOOKUP(C13,Deflatores!G$4:H$38,2,FALSE)*H13+VLOOKUP(C13,Deflatores!G$4:I$38,3,FALSE))) -> 5
A14: US 002 - Manter Relatorio | B14: ALI | C14: I | F14: =IF(ISBLANK(B14),"",IF(I14="L","Baixa",IF(I14="A","Média",IF(I14="","","Alta")))) -> Baixa | G14: =CONCATENATE(B14,I14) -> ALIL | H14: =IF(ISBLANK(B14),"",IF(B14="ALI",IF(I14="L",7,IF(I14="A",10,15)),IF(B14="AIE",IF(I14="L",5,IF(I14="A",7,10)),IF(B14="SE",IF(I14="L",4,IF(I14="A",5,7)),IF(OR(B14="EE",B14="CE"),IF(I14="L",3,IF(I14="A",4,6)),0))))) -> 7 | I14: =IF(OR(ISBLANK(D14),ISBLANK(E14)),IF(OR(B14="ALI",B14="AIE"),"L",IF(OR(B14="EE",B14="SE",B14="CE"),"A","")),IF(B14="EE",IF(E14>=3,IF(D14>=5,"H","A"),IF(E14>=2,IF(D14>=16,"H",IF(D14<=4,"L","A")),IF(D14<=15,"L","A"))),IF(OR(B14="SE",B14="CE"),IF(E14>=4,IF(D14>=6,"H","A"),IF(E14>=2,IF(D14>=20,"H",IF(D14<=5,"L","A")),IF(D14<=19,"L","A"))),IF(OR(B14="ALI",B14="AIE"),IF(E14>=6,IF(D14>=20,"H","A"),IF(E14>=2,IF(D14>=51,"H",IF(D14<=19,"L","A")),IF(D14<=50,"L","A"))),"")))) -> L | J14: =CONCATENATE(B14,C14) -> ALII | K14: =IF(OR(H14="",H14=0),L14,H14) -> 7 | L14: =IF(NOT(ISERROR(VLOOKUP(B14,Deflatores!G$42:H$64,2,FALSE))),VLOOKUP(B14,Deflatores!G$42:H$64,2,FALSE),IF(OR(ISBLANK(C14),ISBLANK(B14)),"",VLOOKUP(C14,Deflatores!G$4:H$38,2,FALSE)*H14+VLOOKUP(C14,Deflatores!G$4:I$38,3,FALSE))) -> 7
A15: US 002 - Manter Relatorio - Consulta | B15: CE | C15: I | F15: =IF(ISBLANK(B15),"",IF(I15="L","Baixa",IF(I15="A","Média",IF(I15="","","Alta")))) -> Média | G15: =CONCATENATE(B15,I15) -> CEA | H15: =IF(ISBLANK(B15),"",IF(B15="ALI",IF(I15="L",7,IF(I15="A",10,15)),IF(B15="AIE",IF(I15="L",5,IF(I15="A",7,10)),IF(B15="SE",IF(I15="L",4,IF(I15="A",5,7)),IF(OR(B15="EE",B15="CE"),IF(I15="L",3,IF(I15="A",4,6)),0))))) -> 4 | I15: =IF(OR(ISBLANK(D15),ISBLANK(E15)),IF(OR(B15="ALI",B15="AIE"),"L",IF(OR(B15="EE",B15="SE",B15="CE"),"A","")),IF(B15="EE",IF(E15>=3,IF(D15>=5,"H","A"),IF(E15>=2,IF(D15>=16,"H",IF(D15<=4,"L","A")),IF(D15<=15,"L","A"))),IF(OR(B15="SE",B15="CE"),IF(E15>=4,IF(D15>=6,"H","A"),IF(E15>=2,IF(D15>=20,"H",IF(D15<=5,"L","A")),IF(D15<=19,"L","A"))),IF(OR(B15="ALI",B15="AIE"),IF(E15>=6,IF(D15>=20,"H","A"),IF(E15>=2,IF(D15>=51,"H",IF(D15<=19,"L","A")),IF(D15<=50,"L","A"))),"")))) -> A | J15: =CONCATENATE(B15,C15) -> CEI | K15: =IF(OR(H15="",H15=0),L15,H15) -> 4 | L15: =IF(NOT(ISERROR(VLOOKUP(B15,Deflatores!G$42:H$64,2,FALSE))),VLOOKUP(B15,Deflatores!G$42:H$64,2,FALSE),IF(OR(ISBLANK(C15),ISBLANK(B15)),"",VLOOKUP(C15,Deflatores!G$4:H$38,2,FALSE)*H15+VLOOKUP(C15,Deflatores!G$4:I$38,3,FALSE))) -> 4
A16: US 002 - Manter Relatorio - Adicionar | B16: EE | C16: I | F16: =IF(ISBLANK(B16),"",IF(I16="L","Baixa",IF(I16="A","Média",IF(I16="","","Alta")))) -> Média | G16: =CONCATENATE(B16,I16) -> EEA | H16: =IF(ISBLANK(B16),"",IF(B16="ALI",IF(I16="L",7,IF(I16="A",10,15)),IF(B16="AIE",IF(I16="L",5,IF(I16="A",7,10)),IF(B16="SE",IF(I16="L",4,IF(I16="A",5,7)),IF(OR(B16="EE",B16="CE"),IF(I16="L",3,IF(I16="A",4,6)),0))))) -> 4 | I16: =IF(OR(ISBLANK(D16),ISBLANK(E16)),IF(OR(B16="ALI",B16="AIE"),"L",IF(OR(B16="EE",B16="SE",B16="CE"),"A","")),IF(B16="EE",IF(E16>=3,IF(D16>=5,"H","A"),IF(E16>=2,IF(D16>=16,"H",IF(D16<=4,"L","A")),IF(D16<=15,"L","A"))),IF(OR(B16="SE",B16="CE"),IF(E16>=4,IF(D16>=6,"H","A"),IF(E16>=2,IF(D16>=20,"H",IF(D16<=5,"L","A")),IF(D16<=19,"L","A"))),IF(OR(B16="ALI",B16="AIE"),IF(E16>=6,IF(D16>=20,"H","A"),IF(E16>=2,IF(D16>=51,"H",IF(D16<=19,"L","A")),IF(D16<=50,"L","A"))),"")))) -> A | J16: =CONCATENATE(B16,C16) -> EEI | K16: =IF(OR(H16="",H16=0),L16,H16) -> 4 | L16: =IF(NOT(ISERROR(VLOOKUP(B16,Deflatores!G$42:H$64,2,FALSE))),VLOOKUP(B16,Deflatores!G$42:H$64,2,FALSE),IF(OR(ISBLANK(C16),ISBLANK(B16)),"",VLOOKUP(C16,Deflatores!G$4:H$38,2,FALSE)*H16+VLOOKUP(C16,Deflatores!G$4:I$38,3,FALSE))) -> 4
A17: US 002 - Manter Relatorio - Alterar | B17: EE | C17: I | F17: =IF(ISBLANK(B17),"",IF(I17="L","Baixa",IF(I17="A","Média",IF(I17="","","Alta")))) -> Média | G17: =CONCATENATE(B17,I17) -> EEA | H17: =IF(ISBLANK(B17),"",IF(B17="ALI",IF(I17="L",7,IF(I17="A",10,15)),IF(B17="AIE",IF(I17="L",5,IF(I17="A",7,10)),IF(B17="SE",IF(I17="L",4,IF(I17="A",5,7)),IF(OR(B17="EE",B17="CE"),IF(I17="L",3,IF(I17="A",4,6)),0))))) -> 4 | I17: =IF(OR(ISBLANK(D17),ISBLANK(E17)),IF(OR(B17="ALI",B17="AIE"),"L",IF(OR(B17="EE",B17="SE",B17="CE"),"A","")),IF(B17="EE",IF(E17>=3,IF(D17>=5,"H","A"),IF(E17>=2,IF(D17>=16,"H",IF(D17<=4,"L","A")),IF(D17<=15,"L","A"))),IF(OR(B17="SE",B17="CE"),IF(E17>=4,IF(D17>=6,"H","A"),IF(E17>=2,IF(D17>=20,"H",IF(D17<=5,"L","A")),IF(D17<=19,"L","A"))),IF(OR(B17="ALI",B17="AIE"),IF(E17>=6,IF(D17>=20,"H","A"),IF(E17>=2,IF(D17>=51,"H",IF(D17<=19,"L","A")),IF(D17<=50,"L","A"))),"")))) -> A | J17: =CONCATENATE(B17,C17) -> EEI | K17: =IF(OR(H17="",H17=0),L17,H17) -> 4 | L17: =IF(NOT(ISERROR(VLOOKUP(B17,Deflatores!G$42:H$64,2,FALSE))),VLOOKUP(B17,Deflatores!G$42:H$64,2,FALSE),IF(OR(ISBLANK(C17),ISBLANK(B17)),"",VLOOKUP(C17,Deflatores!G$4:H$38,2,FALSE)*H17+VLOOKUP(C17,Deflatores!G$4:I$38,3,FALSE))) -> 4
A18: US 002 - Manter Relatorio - Excluir | B18: EE | C18: I | F18: =IF(ISBLANK(B18),"",IF(I18="L","Baixa",IF(I18="A","Média",IF(I18="","","Alta")))) -> Média | G18: =CONCATENATE(B18,I18) -> EEA | H18: =IF(ISBLANK(B18),"",IF(B18="ALI",IF(I18="L",7,IF(I18="A",10,15)),IF(B18="AIE",IF(I18="L",5,IF(I18="A",7,10)),IF(B18="SE",IF(I18="L",4,IF(I18="A",5,7)),IF(OR(B18="EE",B18="CE"),IF(I18="L",3,IF(I18="A",4,6)),0))))) -> 4 | I18: =IF(OR(ISBLANK(D18),ISBLANK(E18)),IF(OR(B18="ALI",B18="AIE"),"L",IF(OR(B18="EE",B18="SE",B18="CE"),"A","")),IF(B18="EE",IF(E18>=3,IF(D18>=5,"H","A"),IF(E18>=2,IF(D18>=16,"H",IF(D18<=4,"L","A")),IF(D18<=15,"L","A"))),IF(OR(B18="SE",B18="CE"),IF(E18>=4,IF(D18>=6,"H","A"),IF(E18>=2,IF(D18>=20,"H",IF(D18<=5,"L","A")),IF(D18<=19,"L","A"))),IF(OR(B18="ALI",B18="AIE"),IF(E18>=6,IF(D18>=20,"H","A"),IF(E18>=2,IF(D18>=51,"H",IF(D18<=19,"L","A")),IF(D18<=50,"L","A"))),"")))) -> A | J18: =CONCATENATE(B18,C18) -> EEI | K18: =IF(OR(H18="",H18=0),L18,H18) -> 4 | L18: =IF(NOT(ISERROR(VLOOKUP(B18,Deflatores!G$42:H$64,2,FALSE))),VLOOKUP(B18,Deflatores!G$42:H$64,2,FALSE),IF(OR(ISBLANK(C18),ISBLANK(B18)),"",VLOOKUP(C18,Deflatores!G$4:H$38,2,FALSE)*H18+VLOOKUP(C18,Deflatores!G$4:I$38,3,FALSE))) -> 4
A19: US 002 - Manter Relatorio - Visualizar | B19: SE | C19: I | F19: =IF(ISBLANK(B19),"",IF(I19="L","Baixa",IF(I19="A","Média",IF(I19="","","Alta")))) -> Média | G19: =CONCATENATE(B19,I19) -> SEA | H19: =IF(ISBLANK(B19),"",IF(B19="ALI",IF(I19="L",7,IF(I19="A",10,15)),IF(B19="AIE",IF(I19="L",5,IF(I19="A",7,10)),IF(B19="SE",IF(I19="L",4,IF(I19="A",5,7)),IF(OR(B19="EE",B19="CE"),IF(I19="L",3,IF(I19="A",4,6)),0))))) -> 5 | I19: =IF(OR(ISBLANK(D19),ISBLANK(E19)),IF(OR(B19="ALI",B19="AIE"),"L",IF(OR(B19="EE",B19="SE",B19="CE"),"A","")),IF(B19="EE",IF(E19>=3,IF(D19>=5,"H","A"),IF(E19>=2,IF(D19>=16,"H",IF(D19<=4,"L","A")),IF(D19<=15,"L","A"))),IF(OR(B19="SE",B19="CE"),IF(E19>=4,IF(D19>=6,"H","A"),IF(E19>=2,IF(D19>=20,"H",IF(D19<=5,"L","A")),IF(D19<=19,"L","A"))),IF(OR(B19="ALI",B19="AIE"),IF(E19>=6,IF(D19>=20,"H","A"),IF(E19>=2,IF(D19>=51,"H",IF(D19<=19,"L","A")),IF(D19<=50,"L","A"))),"")))) -> A | J19: =CONCATENATE(B19,C19) -> SEI | K19: =IF(OR(H19="",H19=0),L19,H19) -> 5 | L19: =IF(NOT(ISERROR(VLOOKUP(B19,Deflatores!G$42:H$64,2,FALSE))),VLOOKUP(B19,Deflatores!G$42:H$64,2,FALSE),IF(OR(ISBLANK(C19),ISBLANK(B19)),"",VLOOKUP(C19,Deflatores!G$4:H$38,2,FALSE)*H19+VLOOKUP(C19,Deflatores!G$4:I$38,3,FALSE))) -> 5
... A86: US 014 - Relatorio Tipo de Usuario - Imprimir | B86: SE | C86: I | F86: =IF(ISBLANK(B86),"",IF(I86="L","Baixa",IF(I86="A","Média",IF(I86="","","Alta")))) -> Média | G86: =CONCATENATE(B86,I86) -> SEA | H86: =IF(ISBLANK(B86),"",IF(B86="ALI",IF(I86="L",7,IF(I86="A",10,15)),IF(B86="AIE",IF(I86="L",5,IF(I86="A",7,10)),IF(B86="SE",IF(I86="L",4,IF(I86="A",5,7)),IF(OR(B86="EE",B86="CE"),IF(I86="L",3,IF(I86="A",4,6)),0))))) -> 5 | I86: =IF(OR(ISBLANK(D86),ISBLANK(E86)),IF(OR(B86="ALI",B86="AIE"),"L",IF(OR(B86="EE",B86="SE",B86="CE"),"A","")),IF(B86="EE",IF(E86>=3,IF(D86>=5,"H","A"),IF(E86>=2,IF(D86>=16,"H",IF(D86<=4,"L","A")),IF(D86<=15,"L","A"))),IF(OR(B86="SE",B86="CE"),IF(E86>=4,IF(D86>=6,"H","A"),IF(E86>=2,IF(D86>=20,"H",IF(D86<=5,"L","A")),IF(D86<=19,"L","A"))),IF(OR(B86="ALI",B86="AIE"),IF(E86>=6,IF(D86>=20,"H","A"),IF(E86>=2,IF(D86>=51,"H",IF(D86<=19,"L","A")),IF(D86<=50,"L","A"))),"")))) -> A | J86: =CONCATENATE(B86,C86) -> SEI | K86: =IF(OR(H86="",H86=0),L86,H86) -> 5 | L86: =IF(NOT(ISERROR(VLOOKUP(B86,Deflatores!G$42:H$64,2,FALSE))),VLOOKUP(B86,Deflatores!G$42:H$64,2,FALSE),IF(OR(ISBLANK(C86),ISBLANK(B86)),"",VLOOKUP(C86,Deflatores!G$4:H$38,2,FALSE)*H86+VLOOKUP(C86,Deflatores!G$4:I$38,3,FALSE))) -> 5
F87: =IF(ISBLANK(B87),"",IF(I87="L","Baixa",IF(I87="A","Média",IF(I87="","","Alta")))) | G87: =CONCATENATE(B87,I87) | H87: =IF(ISBLANK(B87),"",IF(B87="ALI",IF(I87="L",7,IF(I87="A",10,15)),IF(B87="AIE",IF(I87="L",5,IF(I87="A",7,10)),IF(B87="SE",IF(I87="L",4,IF(I87="A",5,7)),IF(OR(B87="EE",B87="CE"),IF(I87="L",3,IF(I87="A",4,6)),0))))) | I87: =IF(OR(ISBLANK(D87),ISBLANK(E87)),IF(OR(B87="ALI",B87="AIE"),"L",IF(OR(B87="EE",B87="SE",B87="CE"),"A","")),IF(B87="EE",IF(E87>=3,IF(D87>=5,"H","A"),IF(E87>=2,IF(D87>=16,"H",IF(D87<=4,"L","A")),IF(D87<=15,"L","A"))),IF(OR(B87="SE",B87="CE"),IF(E87>=4,IF(D87>=6,"H","A"),IF(E87>=2,IF(D87>=20,"H",IF(D87<=5,"L","A")),IF(D87<=19,"L","A"))),IF(OR(B87="ALI",B87="AIE"),IF(E87>=6,IF(D87>=20,"H","A"),IF(E87>=2,IF(D87>=51,"H",IF(D87<=19,"L","A")),IF(D87<=50,"L","A"))),"")))) | J87: =CONCATENATE(B87,C87) | K87: =IF(OR(H87="",H87=0),L87,H87) | L87: =IF(NOT(ISERROR(VLOOKUP(B87,Deflatores!G$42:H$64,2,FALSE))),VLOOKUP(B87,Deflatores!G$42:H$64,2,FALSE),IF(OR(ISBLANK(C87),ISBLANK(B87)),"",VLOOKUP(C87,Deflatores!G$4:H$38,2,FALSE)*H87+VLOOKUP(C87,Deflatores!G$4:I$38,3,FALSE)))
F88: =IF(ISBLANK(B88),"",IF(I88="L","Baixa",IF(I88="A","Média",IF(I88="","","Alta")))) | G88: =CONCATENATE(B88,I88) | H88: =IF(ISBLANK(B88),"",IF(B88="ALI",IF(I88="L",7,IF(I88="A",10,15)),IF(B88="AIE",IF(I88="L",5,IF(I88="A",7,10)),IF(B88="SE",IF(I88="L",4,IF(I88="A",5,7)),IF(OR(B88="EE",B88="CE"),IF(I88="L",3,IF(I88="A",4,6)),0))))) | I88: =IF(OR(ISBLANK(D88),ISBLANK(E88)),IF(OR(B88="ALI",B88="AIE"),"L",IF(OR(B88="EE",B88="SE",B88="CE"),"A","")),IF(B88="EE",IF(E88>=3,IF(D88>=5,"H","A"),IF(E88>=2,IF(D88>=16,"H",IF(D88<=4,"L","A")),IF(D88<=15,"L","A"))),IF(OR(B88="SE",B88="CE"),IF(E88>=4,IF(D88>=6,"H","A"),IF(E88>=2,IF(D88>=20,"H",IF(D88<=5,"L","A")),IF(D88<=19,"L","A"))),IF(OR(B88="ALI",B88="AIE"),IF(E88>=6,IF(D88>=20,"H","A"),IF(E88>=2,IF(D88>=51,"H",IF(D88<=19,"L","A")),IF(D88<=50,"L","A"))),"")))) | J88: =CONCATENATE(B88,C88) | K88: =IF(OR(H88="",H88=0),L88,H88) | L88: =IF(NOT(ISERROR(VLOOKUP(B88,Deflatores!G$42:H$64,2,FALSE))),VLOOKUP(B88,Deflatores!G$42:H$64,2,FALSE),IF(OR(ISBLANK(C88),ISBLANK(B88)),"",VLOOKUP(C88,Deflatores!G$4:H$38,2,FALSE)*H88+VLOOKUP(C88,Deflatores!G$4:I$38,3,FALSE)))
F89: =IF(ISBLANK(B89),"",IF(I89="L","Baixa",IF(I89="A","Média",IF(I89="","","Alta")))) | G89: =CONCATENATE(B89,I89) | H89: =IF(ISBLANK(B89),"",IF(B89="ALI",IF(I89="L",7,IF(I89="A",10,15)),IF(B89="AIE",IF(I89="L",5,IF(I89="A",7,10)),IF(B89="SE",IF(I89="L",4,IF(I89="A",5,7)),IF(OR(B89="EE",B89="CE"),IF(I89="L",3,IF(I89="A",4,6)),0))))) | I89: =IF(OR(ISBLANK(D89),ISBLANK(E89)),IF(OR(B89="ALI",B89="AIE"),"L",IF(OR(B89="EE",B89="SE",B89="CE"),"A","")),IF(B89="EE",IF(E89>=3,IF(D89>=5,"H","A"),IF(E89>=2,IF(D89>=16,"H",IF(D89<=4,"L","A")),IF(D89<=15,"L","A"))),IF(OR(B89="SE",B89="CE"),IF(E89>=4,IF(D89>=6,"H","A"),IF(E89>=2,IF(D89>=20,"H",IF(D89<=5,"L","A")),IF(D89<=19,"L","A"))),IF(OR(B89="ALI",B89="AIE"),IF(E89>=6,IF(D89>=20,"H","A"),IF(E89>=2,IF(D89>=51,"H",IF(D89<=19,"L","A")),IF(D89<=50,"L","A"))),"")))) | J89: =CONCATENATE(B89,C89) | K89: =IF(OR(H89="",H89=0),L89,H89) | L89: =IF(NOT(ISERROR(VLOOKUP(B89,Deflatores!G$42:H$64,2,FALSE))),VLOOKUP(B89,Deflatores!G$42:H$64,2,FALSE),IF(OR(ISBLANK(C89),ISBLANK(B89)),"",VLOOKUP(C89,Deflatores!G$4:H$38,2,FALSE)*H89+VLOOKUP(C89,Deflatores!G$4:I$38,3,FALSE)))
F90: =IF(ISBLANK(B90),"",IF(I90="L","Baixa",IF(I90="A","Média",IF(I90="","","Alta")))) | G90: =CONCATENATE(B90,I90) | H90: =IF(ISBLANK(B90),"",IF(B90="ALI",IF(I90="L",7,IF(I90="A",10,15)),IF(B90="AIE",IF(I90="L",5,IF(I90="A",7,10)),IF(B90="SE",IF(I90="L",4,IF(I90="A",5,7)),IF(OR(B90="EE",B90="CE"),IF(I90="L",3,IF(I90="A",4,6)),0))))) | I90: =IF(OR(ISBLANK(D90),ISBLANK(E90)),IF(OR(B90="ALI",B90="AIE"),"L",IF(OR(B90="EE",B90="SE",B90="CE"),"A","")),IF(B90="EE",IF(E90>=3,IF(D90>=5,"H","A"),IF(E90>=2,IF(D90>=16,"H",IF(D90<=4,"L","A")),IF(D90<=15,"L","A"))),IF(OR(B90="SE",B90="CE"),IF(E90>=4,IF(D90>=6,"H","A"),IF(E90>=2,IF(D90>=20,"H",IF(D90<=5,"L","A")),IF(D90<=19,"L","A"))),IF(OR(B90="ALI",B90="AIE"),IF(E90>=6,IF(D90>=20,"H","A"),IF(E90>=2,IF(D90>=51,"H",IF(D90<=19,"L","A")),IF(D90<=50,"L","A"))),"")))) | J90: =CONCATENATE(B90,C90) | K90: =IF(OR(H90="",H90=0),L90,H90) | L90: =IF(NOT(ISERROR(VLOOKUP(B90,Deflatores!G$42:H$64,2,FALSE))),VLOOKUP(B90,Deflatores!G$42:H$64,2,FALSE),IF(OR(ISBLANK(C90),ISBLANK(B90)),"",VLOOKUP(C90,Deflatores!G$4:H$38,2,FALSE)*H90+VLOOKUP(C90,Deflatores!G$4:I$38,3,FALSE)))
F91: =IF(ISBLANK(B91),"",IF(I91="L","Baixa",IF(I91="A","Média",IF(I91="","","Alta")))) | G91: =CONCATENATE(B91,I91) | H91: =IF(ISBLANK(B91),"",IF(B91="ALI",IF(I91="L",7,IF(I91="A",10,15)),IF(B91="AIE",IF(I91="L",5,IF(I91="A",7,10)),IF(B91="SE",IF(I91="L",4,IF(I91="A",5,7)),IF(OR(B91="EE",B91="CE"),IF(I91="L",3,IF(I91="A",4,6)),0))))) | I91: =IF(OR(ISBLANK(D91),ISBLANK(E91)),IF(OR(B91="ALI",B91="AIE"),"L",IF(OR(B91="EE",B91="SE",B91="CE"),"A","")),IF(B91="EE",IF(E91>=3,IF(D91>=5,"H","A"),IF(E91>=2,IF(D91>=16,"H",IF(D91<=4,"L","A")),IF(D91<=15,"L","A"))),IF(OR(B91="SE",B91="CE"),IF(E91>=4,IF(D91>=6,"H","A"),IF(E91>=2,IF(D91>=20,"H",IF(D91<=5,"L","A")),IF(D91<=19,"L","A"))),IF(OR(B91="ALI",B91="AIE"),IF(E91>=6,IF(D91>=20,"H","A"),IF(E91>=2,IF(D91>=51,"H",IF(D91<=19,"L","A")),IF(D91<=50,"L","A"))),"")))) | J91: =CONCATENATE(B91,C91) | K91: =IF(OR(H91="",H91=0),L91,H91) | L91: =IF(NOT(ISERROR(VLOOKUP(B91,Deflatores!G$42:H$64,2,FALSE))),VLOOKUP(B91,Deflatores!G$42:H$64,2,FALSE),IF(OR(ISBLANK(C91),ISBLANK(B91)),"",VLOOKUP(C91,Deflatores!G$4:H$38,2,FALSE)*H91+VLOOKUP(C91,Deflatores!G$4:I$38,3,FALSE)))
F92: =IF(ISBLANK(B92),"",IF(I92="L","Baixa",IF(I92="A","Média",IF(I92="","","Alta")))) | G92: =CONCATENATE(B92,I92) | H92: =IF(ISBLANK(B92),"",IF(B92="ALI",IF(I92="L",7,IF(I92="A",10,15)),IF(B92="AIE",IF(I92="L",5,IF(I92="A",7,10)),IF(B92="SE",IF(I92="L",4,IF(I92="A",5,7)),IF(OR(B92="EE",B92="CE"),IF(I92="L",3,IF(I92="A",4,6)),0))))) | I92: =IF(OR(ISBLANK(D92),ISBLANK(E92)),IF(OR(B92="ALI",B92="AIE"),"L",IF(OR(B92="EE",B92="SE",B92="CE"),"A","")),IF(B92="EE",IF(E92>=3,IF(D92>=5,"H","A"),IF(E92>=2,IF(D92>=16,"H",IF(D92<=4,"L","A")),IF(D92<=15,"L","A"))),IF(OR(B92="SE",B92="CE"),IF(E92>=4,IF(D92>=6,"H","A"),IF(E92>=2,IF(D92>=20,"H",IF(D92<=5,"L","A")),IF(D92<=19,"L","A"))),IF(OR(B92="ALI",B92="AIE"),IF(E92>=6,IF(D92>=20,"H","A"),IF(E92>=2,IF(D92>=51,"H",IF(D92<=19,"L","A")),IF(D92<=50,"L","A"))),"")))) | J92: =CONCATENATE(B92,C92) | K92: =IF(OR(H92="",H92=0),L92,H92) | L92: =IF(NOT(ISERROR(VLOOKUP(B92,Deflatores!G$42:H$64,2,FALSE))),VLOOKUP(B92,Deflatores!G$42:H$64,2,FALSE),IF(OR(ISBLANK(C92),ISBLANK(B92)),"",VLOOKUP(C92,Deflatores!G$4:H$38,2,FALSE)*H92+VLOOKUP(C92,Deflatores!G$4:I$38,3,FALSE)))
F93: =IF(ISBLANK(B93),"",IF(I93="L","Baixa",IF(I93="A","Média",IF(I93="","","Alta")))) | G93: =CONCATENATE(B93,I93) | H93: =IF(ISBLANK(B93),"",IF(B93="ALI",IF(I93="L",7,IF(I93="A",10,15)),IF(B93="AIE",IF(I93="L",5,IF(I93="A",7,10)),IF(B93="SE",IF(I93="L",4,IF(I93="A",5,7)),IF(OR(B93="EE",B93="CE"),IF(I93="L",3,IF(I93="A",4,6)),0))))) | I93: =IF(OR(ISBLANK(D93),ISBLANK(E93)),IF(OR(B93="ALI",B93="AIE"),"L",IF(OR(B93="EE",B93="SE",B93="CE"),"A","")),IF(B93="EE",IF(E93>=3,IF(D93>=5,"H","A"),IF(E93>=2,IF(D93>=16,"H",IF(D93<=4,"L","A")),IF(D93<=15,"L","A"))),IF(OR(B93="SE",B93="CE"),IF(E93>=4,IF(D93>=6,"H","A"),IF(E93>=2,IF(D93>=20,"H",IF(D93<=5,"L","A")),IF(D93<=19,"L","A"))),IF(OR(B93="ALI",B93="AIE"),IF(E93>=6,IF(D93>=20,"H","A"),IF(E93>=2,IF(D93>=51,"H",IF(D93<=19,"L","A")),IF(D93<=50,"L","A"))),"")))) | J93: =CONCATENATE(B93,C93) | K93: =IF(OR(H93="",H93=0),L93,H93) | L93: =IF(NOT(ISERROR(VLOOKUP(B93,Deflatores!G$42:H$64,2,FALSE))),VLOOKUP(B93,Deflatores!G$42:H$64,2,FALSE),IF(OR(ISBLANK(C93),ISBLANK(B93)),"",VLOOKUP(C93,Deflatores!G$4:H$38,2,FALSE)*H93+VLOOKUP(C93,Deflatores!G$4:I$38,3,FALSE)))
F94: =IF(ISBLANK(B94),"",IF(I94="L","Baixa",IF(I94="A","Média",IF(I94="","","Alta")))) | G94: =CONCATENATE(B94,I94) | H94: =IF(ISBLANK(B94),"",IF(B94="ALI",IF(I94="L",7,IF(I94="A",10,15)),IF(B94="AIE",IF(I94="L",5,IF(I94="A",7,10)),IF(B94="SE",IF(I94="L",4,IF(I94="A",5,7)),IF(OR(B94="EE",B94="CE"),IF(I94="L",3,IF(I94="A",4,6)),0))))) | I94: =IF(OR(ISBLANK(D94),ISBLANK(E94)),IF(OR(B94="ALI",B94="AIE"),"L",IF(OR(B94="EE",B94="SE",B94="CE"),"A","")),IF(B94="EE",IF(E94>=3,IF(D94>=5,"H","A"),IF(E94>=2,IF(D94>=16,"H",IF(D94<=4,"L","A")),IF(D94<=15,"L","A"))),IF(OR(B94="SE",B94="CE"),IF(E94>=4,IF(D94>=6,"H","A"),IF(E94>=2,IF(D94>=20,"H",IF(D94<=5,"L","A")),IF(D94<=19,"L","A"))),IF(OR(B94="ALI",B94="AIE"),IF(E94>=6,IF(D94>=20,"H","A"),IF(E94>=2,IF(D94>=51,"H",IF(D94<=19,"L","A")),IF(D94<=50,"L","A"))),"")))) | J94: =CONCATENATE(B94,C94) | K94: =IF(OR(H94="",H94=0),L94,H94) | L94: =IF(NOT(ISERROR(VLOOKUP(B94,Deflatores!G$42:H$64,2,FALSE))),VLOOKUP(B94,Deflatores!G$42:H$64,2,FALSE),IF(OR(ISBLANK(C94),ISBLANK(B94)),"",VLOOKUP(C94,Deflatores!G$4:H$38,2,FALSE)*H94+VLOOKUP(C94,Deflatores!G$4:I$38,3,FALSE)))
F95: =IF(ISBLANK(B95),"",IF(I95="L","Baixa",IF(I95="A","Média",IF(I95="","","Alta")))) | G95: =CONCATENATE(B95,I95) | H95: =IF(ISBLANK(B95),"",IF(B95="ALI",IF(I95="L",7,IF(I95="A",10,15)),IF(B95="AIE",IF(I95="L",5,IF(I95="A",7,10)),IF(B95="SE",IF(I95="L",4,IF(I95="A",5,7)),IF(OR(B95="EE",B95="CE"),IF(I95="L",3,IF(I95="A",4,6)),0))))) | I95: =IF(OR(ISBLANK(D95),ISBLANK(E95)),IF(OR(B95="ALI",B95="AIE"),"L",IF(OR(B95="EE",B95="SE",B95="CE"),"A","")),IF(B95="EE",IF(E95>=3,IF(D95>=5,"H","A"),IF(E95>=2,IF(D95>=16,"H",IF(D95<=4,"L","A")),IF(D95<=15,"L","A"))),IF(OR(B95="SE",B95="CE"),IF(E95>=4,IF(D95>=6,"H","A"),IF(E95>=2,IF(D95>=20,"H",IF(D95<=5,"L","A")),IF(D95<=19,"L","A"))),IF(OR(B95="ALI",B95="AIE"),IF(E95>=6,IF(D95>=20,"H","A"),IF(E95>=2,IF(D95>=51,"H",IF(D95<=19,"L","A")),IF(D95<=50,"L","A"))),"")))) | J95: =CONCATENATE(B95,C95) | K95: =IF(OR(H95="",H95=0),L95,H95) | L95: =IF(NOT(ISERROR(VLOOKUP(B95,Deflatores!G$42:H$64,2,FALSE))),VLOOKUP(B95,Deflatores!G$42:H$64,2,FALSE),IF(OR(ISBLANK(C95),ISBLANK(B95)),"",VLOOKUP(C95,Deflatores!G$4:H$38,2,FALSE)*H95+VLOOKUP(C95,Deflatores!G$4:I$38,3,FALSE)))
F96: =IF(ISBLANK(B96),"",IF(I96="L","Baixa",IF(I96="A","Média",IF(I96="","","Alta")))) | G96: =CONCATENATE(B96,I96) | H96: =IF(ISBLANK(B96),"",IF(B96="ALI",IF(I96="L",7,IF(I96="A",10,15)),IF(B96="AIE",IF(I96="L",5,IF(I96="A",7,10)),IF(B96="SE",IF(I96="L",4,IF(I96="A",5,7)),IF(OR(B96="EE",B96="CE"),IF(I96="L",3,IF(I96="A",4,6)),0))))) | I96: =IF(OR(ISBLANK(D96),ISBLANK(E96)),IF(OR(B96="ALI",B96="AIE"),"L",IF(OR(B96="EE",B96="SE",B96="CE"),"A","")),IF(B96="EE",IF(E96>=3,IF(D96>=5,"H","A"),IF(E96>=2,IF(D96>=16,"H",IF(D96<=4,"L","A")),IF(D96<=15,"L","A"))),IF(OR(B96="SE",B96="CE"),IF(E96>=4,IF(D96>=6,"H","A"),IF(E96>=2,IF(D96>=20,"H",IF(D96<=5,"L","A")),IF(D96<=19,"L","A"))),IF(OR(B96="ALI",B96="AIE"),IF(E96>=6,IF(D96>=20,"H","A"),IF(E96>=2,IF(D96>=51,"H",IF(D96<=19,"L","A")),IF(D96<=50,"L","A"))),"")))) | J96: =CONCATENATE(B96,C96) | K96: =IF(OR(H96="",H96=0),L96,H96) | L96: =IF(NOT(ISERROR(VLOOKUP(B96,Deflatores!G$42:H$64,2,FALSE))),VLOOKUP(B96,Deflatores!G$42:H$64,2,FALSE),IF(OR(ISBLANK(C96),ISBLANK(B96)),"",VLOOKUP(C96,Deflatores!G$4:H$38,2,FALSE)*H96+VLOOKUP(C96,Deflatores!G$4:I$38,3,FALSE)))
F97: =IF(ISBLANK(B97),"",IF(I97="L","Baixa",IF(I97="A","Média",IF(I97="","","Alta")))) | G97: =CONCATENATE(B97,I97) | H97: =IF(ISBLANK(B97),"",IF(B97="ALI",IF(I97="L",7,IF(I97="A",10,15)),IF(B97="AIE",IF(I97="L",5,IF(I97="A",7,10)),IF(B97="SE",IF(I97="L",4,IF(I97="A",5,7)),IF(OR(B97="EE",B97="CE"),IF(I97="L",3,IF(I97="A",4,6)),0))))) | I97: =IF(OR(ISBLANK(D97),ISBLANK(E97)),IF(OR(B97="ALI",B97="AIE"),"L",IF(OR(B97="EE",B97="SE",B97="CE"),"A","")),IF(B97="EE",IF(E97>=3,IF(D97>=5,"H","A"),IF(E97>=2,IF(D97>=16,"H",IF(D97<=4,"L","A")),IF(D97<=15,"L","A"))),IF(OR(B97="SE",B97="CE"),IF(E97>=4,IF(D97>=6,"H","A"),IF(E97>=2,IF(D97>=20,"H",IF(D97<=5,"L","A")),IF(D97<=19,"L","A"))),IF(OR(B97="ALI",B97="AIE"),IF(E97>=6,IF(D97>=20,"H","A"),IF(E97>=2,IF(D97>=51,"H",IF(D97<=19,"L","A")),IF(D97<=50,"L","A"))),"")))) | J97: =CONCATENATE(B97,C97) | K97: =IF(OR(H97="",H97=0),L97,H97) | L97: =IF(NOT(ISERROR(VLOOKUP(B97,Deflatores!G$42:H$64,2,FALSE))),VLOOKUP(B97,Deflatores!G$42:H$64,2,FALSE),IF(OR(ISBLANK(C97),ISBLANK(B97)),"",VLOOKUP(C97,Deflatores!G$4:H$38,2,FALSE)*H97+VLOOKUP(C97,Deflatores!G$4:I$38,3,FALSE)))
F98: =IF(ISBLANK(B98),"",IF(I98="L","Baixa",IF(I98="A","Média",IF(I98="","","Alta")))) | G98: =CONCATENATE(B98,I98) | H98: =IF(ISBLANK(B98),"",IF(B98="ALI",IF(I98="L",7,IF(I98="A",10,15)),IF(B98="AIE",IF(I98="L",5,IF(I98="A",7,10)),IF(B98="SE",IF(I98="L",4,IF(I98="A",5,7)),IF(OR(B98="EE",B98="CE"),IF(I98="L",3,IF(I98="A",4,6)),0))))) | I98: =IF(OR(ISBLANK(D98),ISBLANK(E98)),IF(OR(B98="ALI",B98="AIE"),"L",IF(OR(B98="EE",B98="SE",B98="CE"),"A","")),IF(B98="EE",IF(E98>=3,IF(D98>=5,"H","A"),IF(E98>=2,IF(D98>=16,"H",IF(D98<=4,"L","A")),IF(D98<=15,"L","A"))),IF(OR(B98="SE",B98="CE"),IF(E98>=4,IF(D98>=6,"H","A"),IF(E98>=2,IF(D98>=20,"H",IF(D98<=5,"L","A")),IF(D98<=19,"L","A"))),IF(OR(B98="ALI",B98="AIE"),IF(E98>=6,IF(D98>=20,"H","A"),IF(E98>=2,IF(D98>=51,"H",IF(D98<=19,"L","A")),IF(D98<=50,"L","A"))),"")))) | J98: =CONCATENATE(B98,C98) | K98: =IF(OR(H98="",H98=0),L98,H98) | L98: =IF(NOT(ISERROR(VLOOKUP(B98,Deflatores!G$42:H$64,2,FALSE))),VLOOKUP(B98,Deflatores!G$42:H$64,2,FALSE),IF(OR(ISBLANK(C98),ISBLANK(B98)),"",VLOOKUP(C98,Deflatores!G$4:H$38,2,FALSE)*H98+VLOOKUP(C98,Deflatores!G$4:I$38,3,FALSE)))
... F175: =IF(ISBLANK(B175),"",IF(I175="L","Baixa",IF(I175="A","Média",IF(I175="","","Alta")))) | G175: =CONCATENATE(B175,I175) | H175: =IF(ISBLANK(B175),"",IF(B175="ALI",IF(I175="L",7,IF(I175="A",10,15)),IF(B175="AIE",IF(I175="L",5,IF(I175="A",7,10)),IF(B175="SE",IF(I175="L",4,IF(I175="A",5,7)),IF(OR(B175="EE",B175="CE"),IF(I175="L",3,IF(I175="A",4,6)),0))))) | I175: =IF(OR(ISBLANK(D175),ISBLANK(E175)),IF(OR(B175="ALI",B175="AIE"),"L",IF(OR(B175="EE",B175="SE",B175="CE"),"A","")),IF(B175="EE",IF(E175>=3,IF(D175>=5,"H","A"),IF(E175>=2,IF(D175>=16,"H",IF(D175<=4,"L","A")),IF(D175<=15,"L","A"))),IF(OR(B175="SE",B175="CE"),IF(E175>=4,IF(D175>=6,"H","A"),IF(E175>=2,IF(D175>=20,"H",IF(D175<=5,"L","A")),IF(D175<=19,"L","A"))),IF(OR(B175="ALI",B175="AIE"),IF(E175>=6,IF(D175>=20,"H","A"),IF(E175>=2,IF(D175>=51,"H",IF(D175<=19,"L","A")),IF(D175<=50,"L","A"))),"")))) | J175: =CONCATENATE(B175,C175) | K175: =IF(OR(H175="",H175=0),L175,H175) | L175: =IF(NOT(ISERROR(VLOOKUP(B175,Deflatores!G$42:H$64,2,FALSE))),VLOOKUP(B175,Deflatores!G$42:H$64,2,FALSE),IF(OR(ISBLANK(C175),ISBLANK(B175)),"",VLOOKUP(C175,Deflatores!G$4:H$38,2,FALSE)*H175+VLOOKUP(C175,Deflatores!G$4:I$38,3,FALSE)))
F176: =IF(ISBLANK(B176),"",IF(I176="L","Baixa",IF(I176="A","Média",IF(I176="","","Alta")))) | G176: =CONCATENATE(B176,I176) | H176: =IF(ISBLANK(B176),"",IF(B176="ALI",IF(I176="L",7,IF(I176="A",10,15)),IF(B176="AIE",IF(I176="L",5,IF(I176="A",7,10)),IF(B176="SE",IF(I176="L",4,IF(I176="A",5,7)),IF(OR(B176="EE",B176="CE"),IF(I176="L",3,IF(I176="A",4,6)),0))))) | I176: =IF(OR(ISBLANK(D176),ISBLANK(E176)),IF(OR(B176="ALI",B176="AIE"),"L",IF(OR(B176="EE",B176="SE",B176="CE"),"A","")),IF(B176="EE",IF(E176>=3,IF(D176>=5,"H","A"),IF(E176>=2,IF(D176>=16,"H",IF(D176<=4,"L","A")),IF(D176<=15,"L","A"))),IF(OR(B176="SE",B176="CE"),IF(E176>=4,IF(D176>=6,"H","A"),IF(E176>=2,IF(D176>=20,"H",IF(D176<=5,"L","A")),IF(D176<=19,"L","A"))),IF(OR(B176="ALI",B176="AIE"),IF(E176>=6,IF(D176>=20,"H","A"),IF(E176>=2,IF(D176>=51,"H",IF(D176<=19,"L","A")),IF(D176<=50,"L","A"))),"")))) | J176: =CONCATENATE(B176,C176) | K176: =IF(OR(H176="",H176=0),L176,H176) | L176: =IF(NOT(ISERROR(VLOOKUP(B176,Deflatores!G$42:H$64,2,FALSE))),VLOOKUP(B176,Deflatores!G$42:H$64,2,FALSE),IF(OR(ISBLANK(C176),ISBLANK(B176)),"",VLOOKUP(C176,Deflatores!G$4:H$38,2,FALSE)*H176+VLOOKUP(C176,Deflatores!G$4:I$38,3,FALSE))) | O176: Fronteira externa com o SISPAT.
F177: =IF(ISBLANK(B177),"",IF(I177="L","Baixa",IF(I177="A","Média",IF(I177="","","Alta")))) | G177: =CONCATENATE(B177,I177) | H177: =IF(ISBLANK(B177),"",IF(B177="ALI",IF(I177="L",7,IF(I177="A",10,15)),IF(B177="AIE",IF(I177="L",5,IF(I177="A",7,10)),IF(B177="SE",IF(I177="L",4,IF(I177="A",5,7)),IF(OR(B177="EE",B177="CE"),IF(I177="L",3,IF(I177="A",4,6)),0))))) | I177: =IF(OR(ISBLANK(D177),ISBLANK(E177)),IF(OR(B177="ALI",B177="AIE"),"L",IF(OR(B177="EE",B177="SE",B177="CE"),"A","")),IF(B177="EE",IF(E177>=3,IF(D177>=5,"H","A"),IF(E177>=2,IF(D177>=16,"H",IF(D177<=4,"L","A")),IF(D177<=15,"L","A"))),IF(OR(B177="SE",B177="CE"),IF(E177>=4,IF(D177>=6,"H","A"),IF(E177>=2,IF(D177>=20,"H",IF(D177<=5,"L","A")),IF(D177<=19,"L","A"))),IF(OR(B177="ALI",B177="AIE"),IF(E177>=6,IF(D177>=20,"H","A"),IF(E177>=2,IF(D177>=51,"H",IF(D177<=19,"L","A")),IF(D177<=50,"L","A"))),"")))) | J177: =CONCATENATE(B177,C177) | K177: =IF(OR(H177="",H177=0),L177,H177) | L177: =IF(NOT(ISERROR(VLOOKUP(B177,Deflatores!G$42:H$64,2,FALSE))),VLOOKUP(B177,Deflatores!G$42:H$64,2,FALSE),IF(OR(ISBLANK(C177),ISBLANK(B177)),"",VLOOKUP(C177,Deflatores!G$4:H$38,2,FALSE)*H177+VLOOKUP(C177,Deflatores!G$4:I$38,3,FALSE)))
F178: =IF(ISBLANK(B178),"",IF(I178="L","Baixa",IF(I178="A","Média",IF(I178="","","Alta")))) | G178: =CONCATENATE(B178,I178) | H178: =IF(ISBLANK(B178),"",IF(B178="ALI",IF(I178="L",7,IF(I178="A",10,15)),IF(B178="AIE",IF(I178="L",5,IF(I178="A",7,10)),IF(B178="SE",IF(I178="L",4,IF(I178="A",5,7)),IF(OR(B178="EE",B178="CE"),IF(I178="L",3,IF(I178="A",4,6)),0))))) | I178: =IF(OR(ISBLANK(D178),ISBLANK(E178)),IF(OR(B178="ALI",B178="AIE"),"L",IF(OR(B178="EE",B178="SE",B178="CE"),"A","")),IF(B178="EE",IF(E178>=3,IF(D178>=5,"H","A"),IF(E178>=2,IF(D178>=16,"H",IF(D178<=4,"L","A")),IF(D178<=15,"L","A"))),IF(OR(B178="SE",B178="CE"),IF(E178>=4,IF(D178>=6,"H","A"),IF(E178>=2,IF(D178>=20,"H",IF(D178<=5,"L","A")),IF(D178<=19,"L","A"))),IF(OR(B178="ALI",B178="AIE"),IF(E178>=6,IF(D178>=20,"H","A"),IF(E178>=2,IF(D178>=51,"H",IF(D178<=19,"L","A")),IF(D178<=50,"L","A"))),"")))) | J178: =CONCATENATE(B178,C178) | K178: =IF(OR(H178="",H178=0),L178,H178) | L178: =IF(NOT(ISERROR(VLOOKUP(B178,Deflatores!G$42:H$64,2,FALSE))),VLOOKUP(B178,Deflatores!G$42:H$64,2,FALSE),IF(OR(ISBLANK(C178),ISBLANK(B178)),"",VLOOKUP(C178,Deflatores!G$4:H$38,2,FALSE)*H178+VLOOKUP(C178,Deflatores!G$4:I$38,3,FALSE)))
F179: =IF(ISBLANK(B179),"",IF(I179="L","Baixa",IF(I179="A","Média",IF(I179="","","Alta")))) | G179: =CONCATENATE(B179,I179) | H179: =IF(ISBLANK(B179),"",IF(B179="ALI",IF(I179="L",7,IF(I179="A",10,15)),IF(B179="AIE",IF(I179="L",5,IF(I179="A",7,10)),IF(B179="SE",IF(I179="L",4,IF(I179="A",5,7)),IF(OR(B179="EE",B179="CE"),IF(I179="L",3,IF(I179="A",4,6)),0))))) | I179: =IF(OR(ISBLANK(D179),ISBLANK(E179)),IF(OR(B179="ALI",B179="AIE"),"L",IF(OR(B179="EE",B179="SE",B179="CE"),"A","")),IF(B179="EE",IF(E179>=3,IF(D179>=5,"H","A"),IF(E179>=2,IF(D179>=16,"H",IF(D179<=4,"L","A")),IF(D179<=15,"L","A"))),IF(OR(B179="SE",B179="CE"),IF(E179>=4,IF(D179>=6,"H","A"),IF(E179>=2,IF(D179>=20,"H",IF(D179<=5,"L","A")),IF(D179<=19,"L","A"))),IF(OR(B179="ALI",B179="AIE"),IF(E179>=6,IF(D179>=20,"H","A"),IF(E179>=2,IF(D179>=51,"H",IF(D179<=19,"L","A")),IF(D179<=50,"L","A"))),"")))) | J179: =CONCATENATE(B179,C179) | K179: =IF(OR(H179="",H179=0),L179,H179) | L179: =IF(NOT(ISERROR(VLOOKUP(B179,Deflatores!G$42:H$64,2,FALSE))),VLOOKUP(B179,Deflatores!G$42:H$64,2,FALSE),IF(OR(ISBLANK(C179),ISBLANK(B179)),"",VLOOKUP(C179,Deflatores!G$4:H$38,2,FALSE)*H179+VLOOKUP(C179,Deflatores!G$4:I$38,3,FALSE)))
F180: =IF(ISBLANK(B180),"",IF(I180="L","Baixa",IF(I180="A","Média",IF(I180="","","Alta")))) | G180: =CONCATENATE(B180,I180) | H180: =IF(ISBLANK(B180),"",IF(B180="ALI",IF(I180="L",7,IF(I180="A",10,15)),IF(B180="AIE",IF(I180="L",5,IF(I180="A",7,10)),IF(B180="SE",IF(I180="L",4,IF(I180="A",5,7)),IF(OR(B180="EE",B180="CE"),IF(I180="L",3,IF(I180="A",4,6)),0))))) | I180: =IF(OR(ISBLANK(D180),ISBLANK(E180)),IF(OR(B180="ALI",B180="AIE"),"L",IF(OR(B180="EE",B180="SE",B180="CE"),"A","")),IF(B180="EE",IF(E180>=3,IF(D180>=5,"H","A"),IF(E180>=2,IF(D180>=16,"H",IF(D180<=4,"L","A")),IF(D180<=15,"L","A"))),IF(OR(B180="SE",B180="CE"),IF(E180>=4,IF(D180>=6,"H","A"),IF(E180>=2,IF(D180>=20,"H",IF(D180<=5,"L","A")),IF(D180<=19,"L","A"))),IF(OR(B180="ALI",B180="AIE"),IF(E180>=6,IF(D180>=20,"H","A"),IF(E180>=2,IF(D180>=51,"H",IF(D180<=19,"L","A")),IF(D180<=50,"L","A"))),"")))) | J180: =CONCATENATE(B180,C180) | K180: =IF(OR(H180="",H180=0),L180,H180) | L180: =IF(NOT(ISERROR(VLOOKUP(B180,Deflatores!G$42:H$64,2,FALSE))),VLOOKUP(B180,Deflatores!G$42:H$64,2,FALSE),IF(OR(ISBLANK(C180),ISBLANK(B180)),"",VLOOKUP(C180,Deflatores!G$4:H$38,2,FALSE)*H180+VLOOKUP(C180,Deflatores!G$4:I$38,3,FALSE)))
F181: =IF(ISBLANK(B181),"",IF(I181="L","Baixa",IF(I181="A","Média",IF(I181="","","Alta")))) | G181: =CONCATENATE(B181,I181) | H181: =IF(ISBLANK(B181),"",IF(B181="ALI",IF(I181="L",7,IF(I181="A",10,15)),IF(B181="AIE",IF(I181="L",5,IF(I181="A",7,10)),IF(B181="SE",IF(I181="L",4,IF(I181="A",5,7)),IF(OR(B181="EE",B181="CE"),IF(I181="L",3,IF(I181="A",4,6)),0))))) | I181: =IF(OR(ISBLANK(D181),ISBLANK(E181)),IF(OR(B181="ALI",B181="AIE"),"L",IF(OR(B181="EE",B181="SE",B181="CE"),"A","")),IF(B181="EE",IF(E181>=3,IF(D181>=5,"H","A"),IF(E181>=2,IF(D181>=16,"H",IF(D181<=4,"L","A")),IF(D181<=15,"L","A"))),IF(OR(B181="SE",B181="CE"),IF(E181>=4,IF(D181>=6,"H","A"),IF(E181>=2,IF(D181>=20,"H",IF(D181<=5,"L","A")),IF(D181<=19,"L","A"))),IF(OR(B181="ALI",B181="AIE"),IF(E181>=6,IF(D181>=20,"H","A"),IF(E181>=2,IF(D181>=51,"H",IF(D181<=19,"L","A")),IF(D181<=50,"L","A"))),"")))) | J181: =CONCATENATE(B181,C181) | K181: =IF(OR(H181="",H181=0),L181,H181) | L181: =IF(NOT(ISERROR(VLOOKUP(B181,Deflatores!G$42:H$64,2,FALSE))),VLOOKUP(B181,Deflatores!G$42:H$64,2,FALSE),IF(OR(ISBLANK(C181),ISBLANK(B181)),"",VLOOKUP(C181,Deflatores!G$4:H$38,2,FALSE)*H181+VLOOKUP(C181,Deflatores!G$4:I$38,3,FALSE)))
F182: =IF(ISBLANK(B182),"",IF(I182="L","Baixa",IF(I182="A","Média",IF(I182="","","Alta")))) | G182: =CONCATENATE(B182,I182) | H182: =IF(ISBLANK(B182),"",IF(B182="ALI",IF(I182="L",7,IF(I182="A",10,15)),IF(B182="AIE",IF(I182="L",5,IF(I182="A",7,10)),IF(B182="SE",IF(I182="L",4,IF(I182="A",5,7)),IF(OR(B182="EE",B182="CE"),IF(I182="L",3,IF(I182="A",4,6)),0))))) | I182: =IF(OR(ISBLANK(D182),ISBLANK(E182)),IF(OR(B182="ALI",B182="AIE"),"L",IF(OR(B182="EE",B182="SE",B182="CE"),"A","")),IF(B182="EE",IF(E182>=3,IF(D182>=5,"H","A"),IF(E182>=2,IF(D182>=16,"H",IF(D182<=4,"L","A")),IF(D182<=15,"L","A"))),IF(OR(B182="SE",B182="CE"),IF(E182>=4,IF(D182>=6,"H","A"),IF(E182>=2,IF(D182>=20,"H",IF(D182<=5,"L","A")),IF(D182<=19,"L","A"))),IF(OR(B182="ALI",B182="AIE"),IF(E182>=6,IF(D182>=20,"H","A"),IF(E182>=2,IF(D182>=51,"H",IF(D182<=19,"L","A")),IF(D182<=50,"L","A"))),"")))) | J182: =CONCATENATE(B182,C182) | K182: =IF(OR(H182="",H182=0),L182,H182) | L182: =IF(NOT(ISERROR(VLOOKUP(B182,Deflatores!G$42:H$64,2,FALSE))),VLOOKUP(B182,Deflatores!G$42:H$64,2,FALSE),IF(OR(ISBLANK(C182),ISBLANK(B182)),"",VLOOKUP(C182,Deflatores!G$4:H$38,2,FALSE)*H182+VLOOKUP(C182,Deflatores!G$4:I$38,3,FALSE)))
F183: =IF(ISBLANK(B183),"",IF(I183="L","Baixa",IF(I183="A","Média",IF(I183="","","Alta")))) | G183: =CONCATENATE(B183,I183) | H183: =IF(ISBLANK(B183),"",IF(B183="ALI",IF(I183="L",7,IF(I183="A",10,15)),IF(B183="AIE",IF(I183="L",5,IF(I183="A",7,10)),IF(B183="SE",IF(I183="L",4,IF(I183="A",5,7)),IF(OR(B183="EE",B183="CE"),IF(I183="L",3,IF(I183="A",4,6)),0))))) | I183: =IF(OR(ISBLANK(D183),ISBLANK(E183)),IF(OR(B183="ALI",B183="AIE"),"L",IF(OR(B183="EE",B183="SE",B183="CE"),"A","")),IF(B183="EE",IF(E183>=3,IF(D183>=5,"H","A"),IF(E183>=2,IF(D183>=16,"H",IF(D183<=4,"L","A")),IF(D183<=15,"L","A"))),IF(OR(B183="SE",B183="CE"),IF(E183>=4,IF(D183>=6,"H","A"),IF(E183>=2,IF(D183>=20,"H",IF(D183<=5,"L","A")),IF(D183<=19,"L","A"))),IF(OR(B183="ALI",B183="AIE"),IF(E183>=6,IF(D183>=20,"H","A"),IF(E183>=2,IF(D183>=51,"H",IF(D183<=19,"L","A")),IF(D183<=50,"L","A"))),"")))) | J183: =CONCATENATE(B183,C183) | K183: =IF(OR(H183="",H183=0),L183,H183) | L183: =IF(NOT(ISERROR(VLOOKUP(B183,Deflatores!G$42:H$64,2,FALSE))),VLOOKUP(B183,Deflatores!G$42:H$64,2,FALSE),IF(OR(ISBLANK(C183),ISBLANK(B183)),"",VLOOKUP(C183,Deflatores!G$4:H$38,2,FALSE)*H183+VLOOKUP(C183,Deflatores!G$4:I$38,3,FALSE)))
F184: =IF(ISBLANK(B184),"",IF(I184="L","Baixa",IF(I184="A","Média",IF(I184="","","Alta")))) | G184: =CONCATENATE(B184,I184) | H184: =IF(ISBLANK(B184),"",IF(B184="ALI",IF(I184="L",7,IF(I184="A",10,15)),IF(B184="AIE",IF(I184="L",5,IF(I184="A",7,10)),IF(B184="SE",IF(I184="L",4,IF(I184="A",5,7)),IF(OR(B184="EE",B184="CE"),IF(I184="L",3,IF(I184="A",4,6)),0))))) | I184: =IF(OR(ISBLANK(D184),ISBLANK(E184)),IF(OR(B184="ALI",B184="AIE"),"L",IF(OR(B184="EE",B184="SE",B184="CE"),"A","")),IF(B184="EE",IF(E184>=3,IF(D184>=5,"H","A"),IF(E184>=2,IF(D184>=16,"H",IF(D184<=4,"L","A")),IF(D184<=15,"L","A"))),IF(OR(B184="SE",B184="CE"),IF(E184>=4,IF(D184>=6,"H","A"),IF(E184>=2,IF(D184>=20,"H",IF(D184<=5,"L","A")),IF(D184<=19,"L","A"))),IF(OR(B184="ALI",B184="AIE"),IF(E184>=6,IF(D184>=20,"H","A"),IF(E184>=2,IF(D184>=51,"H",IF(D184<=19,"L","A")),IF(D184<=50,"L","A"))),"")))) | J184: =CONCATENATE(B184,C184) | K184: =IF(OR(H184="",H184=0),L184,H184) | L184: =IF(NOT(ISERROR(VLOOKUP(B184,Deflatores!G$42:H$64,2,FALSE))),VLOOKUP(B184,Deflatores!G$42:H$64,2,FALSE),IF(OR(ISBLANK(C184),ISBLANK(B184)),"",VLOOKUP(C184,Deflatores!G$4:H$38,2,FALSE)*H184+VLOOKUP(C184,Deflatores!G$4:I$38,3,FALSE)))
...

Sheet Deflatores
A1: Itens Não Mensuráveis
A2: Tipo de Manutenção na Função | G2: Sigla | H2: Contribuição em PF Local | J2: PF IFPUG | K2: PF Local FS
A3: Contrato | B3: Descrição | F3: Origem | H3: Percentual (%) | I3: Fixa (PF)
A4: Adicionada | B4: Inclusão | G4: I | H4: 1 | J4: =SUMIF(#REF!,Deflatores!G4,#REF!) -> #N/A | K4: =IF(H4="",COUNTIF(#REF!,G4)*I4,H4*J4) -> #N/A
A5: Alterada | B5: Alteração (sem conhecimento do Fator de Impacto) | F5: SISP – 4.2 Projeto de Melhoria | G5: A | H5: 0.5 | J5: =SUMIF(#REF!,Deflatores!G5,#REF!) -> #N/A | K5: =IF(H5="",COUNTIF(#REF!,G5)*I5,H5*J5) -> #N/A
A6: Excluída | B6: Exclusão | F6: SISP – 4.2 Projeto de Melhoria | G6: E | H6: 0.4 | J6: =SUMIF(#REF!,Deflatores!G6,#REF!) -> #N/A | K6: =IF(H6="",COUNTIF(#REF!,G6)*I6,H6*J6) -> #N/A
B7: Alteração (50%) de função desenvolvida ou já alterada pela empresa atual | F7: SISP – 4.2 Projeto de Melhoria | G7: A50 | H7: 0.5 | J7: =SUMIF(#REF!,Deflatores!G7,#REF!) -> #N/A | K7: =IF(H7="",COUNTIF(#REF!,G7)*I7,H7*J7) -> #N/A
B8: Alteração (75%) de função não desenv. e ainda não alterada pela empresa atual | F8: SISP – 4.2 Projeto de Melhoria | G8: A75 | H8: 0.75 | J8: =SUMIF(#REF!,Deflatores!G8,#REF!) -> #N/A | K8: =IF(H8="",COUNTIF(#REF!,G8)*I8,H8*J8) -> #N/A
B9: Alteração (75%+15%): o mesmo acima + redocumentar a função | F9: SISP – 4.2 Projeto de Melhoria | G9: A90 | H9: 0.9 | J9: =SUMIF(#REF!,Deflatores!G9,#REF!) -> #N/A | K9: =IF(H9="",COUNTIF(#REF!,G9)*I9,H9*J9) -> #N/A
B10: Migração de Dados | F10: SISP – 4.3 Projetos de Migração de Dados | G10: PMD | H10: 1 | J10: =SUMIF(#REF!,Deflatores!G10,#REF!) -> #N/A | K10: =IF(H10="",COUNTIF(#REF!,G10)*I10,H10*J10) -> #N/A
B11: Corretiva (sem conhecimento do Fator de Impacto) | F11: SISP – 4.4 Manutenção Corretiva | G11: COR | H11: 0.5 | J11: =SUMIF(#REF!,Deflatores!G11,#REF!) -> #N/A | K11: =IF(H11="",COUNTIF(#REF!,G11)*I11,H11*J11) -> #N/A
B12: Corretiva (50%) - Fora da garantia (mesma empresa) | F12: SISP – 4.4 Manutenção Corretiva | G12: COR50 | H12: 0.5 | J12: =SUMIF(#REF!,Deflatores!G12,#REF!) -> #N/A | K12: =IF(H12="",COUNTIF(#REF!,G12)*I12,H12*J12) -> #N/A
B13: Corretiva (75%) - Fora da garantia (outra empresa) | F13: SISP – 4.4 Manutenção Corretiva | G13: COR75 | H13: 0.75 | J13: =SUMIF(#REF!,Deflatores!G13,#REF!) -> #N/A | K13: =IF(H13="",COUNTIF(#REF!,G13)*I13,H13*J13) -> #N/A
B14: Corretiva (75%+15%) - Fora da garantia (outra empresa) + Redocumentação | F14: SISP – 4.4 Manutenção Corretiva | G14: COR90 | H14: 0.9 | J14: =SUMIF(#REF!,Deflatores!G14,#REF!) -> #N/A | K14: =IF(H14="",COUNTIF(#REF!,G14)*I14,H14*J14) -> #N/A
B15: Corretiva em Garantia | F15: SISP – 4.4 Manutenção Corretiva | G15: GAR | H15: 0 | J15: =SUMIF(#REF!,Deflatores!G15,#REF!) -> #N/A | K15: =IF(H15="",COUNTIF(#REF!,G15)*I15,H15*J15) -> #N/A
B16: Mudança de Plataforma - Linguagem de Programação | F16: SISP – 4.5.1 Mudança de Plataforma – Linguagem de Programação | G16: MLP | H16: 1 | J16: =SUMIF(#REF!,Deflatores!G16,#REF!) -> #N/A | K16: =IF(H16="",COUNTIF(#REF!,G16)*I16,H16*J16) -> #N/A
B17: Mudança de Plataforma - Banco de Dados (outro paradigma) | F17: SISP – 4.5.2 Mudança de Plataforma – Banco de Dados | G17: MBO | H17: 1 | J17: =SUMIF(#REF!,Deflatores!G17,#REF!) -> #N/A | K17: =IF(H17="",COUNTIF(#REF!,G17)*I17,H17*J17) -> #N/A
B18: Mudança de Plataforma - Banco de Dados (mesmo paradigma com alterações) | F18: SISP – 4.5.2 Mudança de Plataforma – Banco de Dados | G18: MBM | H18: 0.3 | J18: =SUMIF(#REF!,Deflatores!G18,#REF!) -> #N/A | K18: =IF(H18="",COUNTIF(#REF!,G18)*I18,H18*J18) -> #N/A
... B21: Atualização de Versão – Banco de Dados | F21: SISP – 4.6.3 Atualização de Versão – Banco de Dados | G21: ABD | H21: 0.3 | J21: =SUMIF(#REF!,Deflatores!G21,#REF!) -> #N/A | K21: =IF(H21="",COUNTIF(#REF!,G21)*I21,H21*J21) -> #N/A
B22: Manutenção Cosmética | F22: SISP – 4.7 Manutenção Cosmética | G22: COS | I22: 0.6 | J22: =SUMIF(#REF!,Deflatores!G22,#REF!) -> #N/A | K22: =IF(H22="",COUNTIF(#REF!,G22)*I22,H22*J22) -> #REF!
B23: Adaptação em Funcionalidades sem Alteração de Requisitos Funcionais (sem conhecimento do Fator de Impacto) | F23: SISP – 4.8 Adaptação em Funcionalidades sem Alteração de Requisitos Funcionais | G23: ARN | H23: 0.5 | J23: =SUMIF(#REF!,Deflatores!G23,#REF!) -> #N/A | K23: =IF(H23="",COUNTIF(#REF!,G23)*I23,H23*J23) -> #N/A
B24: Adaptação em Funcionalidades sem Alteração de Requisitos Funcionais (50%) (em função desenvolvida ou já alterada pela empresa atual) | F24: SISP – 4.8 Adaptação em Funcionalidades sem Alteração de Requisitos Funcionais | G24: ARN50 | H24: 0.5 | J24: =SUMIF(#REF!,Deflatores!G24,#REF!) -> #N/A | K24: =IF(H24="",COUNTIF(#REF!,G24)*I24,H24*J24) -> #N/A
B25: Adaptação em Funcionalidades sem Alteração de Requisitos Funcionais (75%) (em função não desenvolvida e ainda não alterada pela empresa atual) | F25: SISP – 4.8 Adaptação em Funcionalidades sem Alteração de Requisitos Funcionais | G25: ARN75 | H25: 0.75 | J25: =SUMIF(#REF!,Deflatores!G25,#REF!) -> #N/A | K25: =IF(H25="",COUNTIF(#REF!,G25)*I25,H25*J25) -> #N/A
B26: Atualização de Dados sem Consulta Prévia | F26: SISP – 4.9.1 Apuração Especial – Base de Dados | G26: ADS | H26: 1 | J26: =SUMIF(#REF!,Deflatores!G26,#REF!) -> #N/A | K26: =IF(H26="",COUNTIF(#REF!,G26)*I26,H26*J26) -> #N/A
B27: Consulta Prévia sem Atualização | F27: SISP – 4.9.1 Apuração Especial – Base de Dados | G27: CPA | H27: 1 | J27: =SUMIF(#REF!,Deflatores!G27,#REF!) -> #N/A | K27: =IF(H27="",COUNTIF(#REF!,G27)*I27,H27*J27) -> #N/A
B28: Atualização de Dados com Consulta Prévia | F28: SISP – 4.9.1 Apuração Especial – Base de Dados | G28: ADC | H28: 0.6 | J28: =SUMIF(#REF!,Deflatores!G28,#REF!) -> #N/A | K28: =IF(H28="",COUNTIF(#REF!,G28)*I28,H28*J28) -> #N/A
B29: Apuração Especial – Geração de Relatórios | F29: SISP – 4.9.2 Apuração Especial – Geração de Relatórios | G29: AGR | H29: 1 | J29: =SUMIF(#REF!,Deflatores!G29,#REF!) -> #N/A | K29: =IF(H29="",COUNTIF(#REF!,G29)*I29,H29*J29) -> #N/A
B30: Apuração Especial – Reexecução | F30: SISP – 4.9.3 Apuração Especial – Reexecução | G30: AER | H30: 0.1 | J30: =SUMIF(#REF!,Deflatores!G30,#REF!) -> #N/A | K30: =IF(H30="",COUNTIF(#REF!,G30)*I30,H30*J30) -> #N/A
B31: Atualização de Dados | F31: SISP – 4.10 Atualização de Dados | G31: ATD | H31: 0.1 | J31: =SUMIF(#REF!,Deflatores!G31,#REF!) -> #N/A | K31: =IF(H31="",COUNTIF(#REF!,G31)*I31,H31*J31) -> #N/A
B32: Manutenção de Documentação de Sistemas Legados | F32: SISP – 4.12 Manutenção de Documentação de Sistemas Legados | G32: MSL | H32: 0.25 | J32: =SUMIF(#REF!,Deflatores!G32,#REF!) -> #N/A | K32: =IF(H32="",COUNTIF(#REF!,G32)*I32,H32*J32) -> #N/A
B33: Verificação de Erros (Sem Documentação de Teste existente) | F33: SISP – 4.13 Verificação de Erros | G33: VES | H33: 0.2 | J33: =SUMIF(#REF!,Deflatores!G33,#REF!) -> #N/A | K33: =IF(H33="",COUNTIF(#REF!,G33)*I33,H33*J33) -> #N/A
B34: Verificação de Erros (Com Documentação de Teste existente) | F34: SISP – 4.13 Verificação de Erros | G34: VEC | H34: 0.15 | J34: =SUMIF(#REF!,Deflatores!G34,#REF!) -> #N/A | K34: =IF(H34="",COUNTIF(#REF!,G34)*I34,H34*J34) -> #N/A
... B36: Componente Interno Reusável | F36: SISP – 4.15 Componente Interno Reusável | G36: CIR | H36: 1 | J36: =SUMIF(#REF!,Deflatores!G36,#REF!) -> #N/A | K36: =IF(H36="",COUNTIF(#REF!,G36)*I36,H36*J36) -> #N/A
G37: . | J37: =SUMIF(#REF!,Deflatores!G37,#REF!) -> #N/A | K37: =IF(H37="",COUNTIF(#REF!,G37)*I37,H37*J37) -> #REF! | L37: ALI
G38: . | J38: =SUMIF(#REF!,Deflatores!G38,#REF!) -> #N/A | K38: =IF(H38="",COUNTIF(#REF!,G38)*I38,H38*J38) -> #REF! | L38: AIE
L39: EE
A40: Itens Não Mensuráveis | G40: Sigla | H40: Contribuição em PF Local | J40: Quantidade | K40: PF Local FS | L40: CE
A41: Contrato | B41: Descrição | F41: Origem | L41: SE
B42: Páginas Estáticas | F42: SISP – 4.11 Desenvolvimento, Manutenção e Publicação de Paginas Estáticas de Intranet, Internet ou Portal | G42: PAG | H42: 0.6 | J42: =COUNTIF(#REF!,G42) -> #REF! | K42: =SUMIF(#REF!,$G42,#REF!) -> #N/A | L42: =""&G42 -> PAG
B43: Manutenção Cosmética (atrelada a algo não funcional) | F43: SISP – 4.7 Manutenção Cosmética | G43: COSNF | H43: 0.6 | J43: =COUNTIF(#REF!,G43) -> #REF! | K43: =SUMIF(#REF!,$G43,#REF!) -> #N/A | L43: =""&G43 -> COSNF
...

Sheet Sumário 1
A1: Sumário da Contagem
A4: =Contagem!A5&" : "&Contagem!F5 -> Aplicação : MANOPLA | F4: =Contagem!A8&" : "&Contagem!F8 -> Projeto : MANOPLA
A5: =Contagem!A9&" : "&Contagem!F9 -> Responsável : João Cleber | F5: =Contagem!A10&" : "&Contagem!F10 -> Revisor : João Cleber
A6: =Contagem!A4&" : "&Contagem!F4 -> Empresa : Secretaria de Estado de Planejamento e Gestão de Mato Grosso | F6: ="Tipo de Contagem : "&Contagem!F6 -> Tipo de Contagem : Aplicação
A7: Tipo de Função | C7: Complexidade Funcional | G7: Total PF IFPUG por Complexidade | H7: % | J7: Total PF Local FS por tipo de manutenção básica | L7: %
B10: EE | C10: =COUNTIF(#REF!,"EEL") -> #REF! | E10: Baixa | F10: x 3 | G10: =C10*3 -> #REF! | J10: =Deflatores!$G$4&"=" -> I= | K10: =SUMIF(#REF!,"EE"&Deflatores!G4,#REF!) -> #N/A
C11: =COUNTIF(#REF!,"EEA") -> #REF! | E11: Média | F11: x 4 | G11: =C11*4 -> #REF! | J11: =Deflatores!$G$5&"=" -> A= | K11: =SUMIF(#REF!,"EE"&Deflatores!G5,#REF!) -> #N/A
C12: =COUNTIF(#REF!,"EEH") -> #REF! | E12: Alta | F12: x 6 | G12: =C12*6 -> #REF! | J12: =Deflatores!$G$6&"=" -> E= | K12: =SUMIF(#REF!,"EE"&Deflatores!G6,#REF!) -> #N/A
B14: Qtd Total | C14: =SUM(C10:C12) -> #REF! | F14: Total | G14: =SUM(G10:G12) -> #REF! | H14: =IF($G$45<>0,G14/$G$45,"") -> #REF! | K14: =SUM(K10:K13) -> #N/A | L14: =IF('Sumário 2'!L11<>0,K14/'Sumário 2'!L11,"") -> #REF!
B17: SE | C17: =COUNTIF(#REF!,"SEL") -> #REF! | E17: Baixa | F17: x 4 | G17: =C17*4 -> #REF! | J17: =Deflatores!$G$4&"=" -> I= | K17: =SUMIF(#REF!,"SE"&Deflatores!$G$4,#REF!) -> #N/A
C18: =COUNTIF(#REF!,"SEA") -> #REF! | E18: Média | F18: x 5 | G18: =C18*5 -> #REF! | J18: =Deflatores!$G$5&"=" -> A= | K18: =SUMIF(#REF!,"SE"&Deflatores!$G$5,#REF!) -> #N/A
C19: =COUNTIF(#REF!,"SEH") -> #REF! | E19: Alta | F19: x 7 | G19: =C19*7 -> #REF! | J19: =Deflatores!$G$6&"=" -> E= | K19: =SUMIF(#REF!,"SE"&Deflatores!$G$6,#REF!) -> #N/A
B21: Qtd Total | C21: =SUM(C17:C19) -> #REF! | F21: Total | G21: =SUM(G17:G19) -> #REF! | H21: =IF($G$45<>0,G21/$G$45,"") -> #REF! | K21: =SUM(K17:K20) -> #N/A | L21: =IF('Sumário 2'!L11<>0,K21/'Sumário 2'!L11,"") -> #REF!
B24: CE | C24: =COUNTIF(#REF!,"CEL") -> #REF! | E24: Baixa | F24: x 3 | G24: =C24*3 -> #REF! | J24: =Deflatores!$G$4&"=" -> I= | K24: =SUMIF(#REF!,"CE"&Deflatores!$G$4,#REF!) -> #N/A
C25: =COUNTIF(#REF!,"CEA") -> #REF! | E25: Média | F25: x 4 | G25: =C25*4 -> #REF! | J25: =Deflatores!$G$5&"=" -> A= | K25: =SUMIF(#REF!,"CE"&Deflatores!$G$5,#REF!) -> #N/A
C26: =COUNTIF(#REF!,"CEH") -> #REF! | E26: Alta | F26: x 6 | G26: =C26*6 -> #REF! | J26: =Deflatores!$G$6&"=" -> E= | K26: =SUMIF(#REF!,"CE"&Deflatores!$G$6,#REF!) -> #N/A
B28: Qtd Total | C28: =SUM(C24:C26) -> #REF! | F28: Total | G28: =SUM(G24:G26) -> #REF! | H28: =IF($G$45<>0,G28/$G$45,"") -> #REF! | K28: =SUM(K24:K27) -> #N/A | L28: =IF('Sumário 2'!L11<>0,K28/'Sumário 2'!L11,"") -> #REF!
B31: ALI | C31: =COUNTIF(#REF!,"ALIL") -> #REF! | E31: Baixa | F31: x 7 | G31: =C31*7 -> #REF! | J31: =Deflatores!$G$4&"=" -> I= | K31: =SUMIF(#REF!,"ALI"&Deflatores!$G$4,#REF!) -> #N/A
C32: =COUNTIF(#REF!,"ALIA") -> #REF! | E32: Média | F32: x 10 | G32: =C32*10 -> #REF! | J32: =Deflatores!$G$5&"=" -> A= | K32: =SUMIF(#REF!,"ALI"&Deflatores!$G$5,#REF!) -> #N/A
C33: =COUNTIF(#REF!,"ALIH") -> #REF! | E33: Alta | F33: x 15 | G33: =C33*15 -> #REF! | J33: =Deflatores!$G$6&"=" -> E= | K33: =SUMIF(#REF!,"ALI"&Deflatores!$G$6,#REF!) -> #N/A
B35: Qtd Total | C35: =SUM(C31:C33) -> #REF! | F35: Total | G35: =SUM(G31:G33) -> #REF! | H35: =IF($G$45<>0,G35/$G$45,"") -> #REF! | K35: =SUM(K31:K34) -> #N/A | L35: =IF('Sumário 2'!L11<>0,K35/'Sumário 2'!L11,"") -> #REF!
B38: AIE | C38: =COUNTIF(#REF!,"AIEL") -> #REF! | E38: Baixa | F38: x 5 | G38: =C38*5 -> #REF! | J38: =Deflatores!$G$4&"=" -> I= | K38: =SUMIF(#REF!,"AIE"&Deflatores!$G$4,#REF!) -> #N/A
C39: =COUNTIF(#REF!,"AIEA") -> #REF! | E39: Média | F39: x 7 | G39: =C39*7 -> #REF! | J39: =Deflatores!$G$5&"=" -> A= | K39: =SUMIF(#REF!,"AIE"&Deflatores!$G$5,#REF!) -> #N/A
C40: =COUNTIF(#REF!,"AIEH") -> #REF! | E40: Alta | F40: x 10 | G40: =C40*10 -> #REF! | J40: =Deflatores!$G$6&"=" -> E= | K40: =SUMIF(#REF!,"AIE"&Deflatores!$G$6,#REF!) -> #N/A
B42: Qtd Total | C42: =SUM(C38:C40) -> #REF! | F42: Total | G42: =SUM(G38:G40) -> #REF! | H42: =IF($G$45<>0,G42/$G$45,"") -> #REF! | K42: =SUM(K38:K41) -> #N/A | L42: =IF('Sumário 2'!L11<>0,K42/'Sumário 2'!L11,"") -> #REF!
B45: Total PF não ajustados (contagem detalhada) | G45: =SUM(G14+G21+G28+G35+G42) -> #REF!
B46: Total PF não ajustados (contagem estimativa) | G46: =(C10+C11+C12)*4+(C17+C18+C19)*5+(C24+C25+C26)*4+(C31+C32+C33)*7+(C38+C39+C40)*5 -> #REF!
B47: Total PF não ajustados (contagem indicativa) | G47: =(C31+C32+C33)*35+(C38+C39+C40)*15 -> #REF!

Sheet Sumário 2
A1: Sumário por Deflatores e Itens não mensuráveis
A4: =Contagem!A5&" : "&Contagem!F5 -> Aplicação : MANOPLA | F4: =Contagem!A8&" : "&Contagem!F8 -> Projeto : MANOPLA
A5: =Contagem!A9&" : "&Contagem!F9 -> Responsável : João Cleber | F5: =Contagem!A10&" : "&Contagem!F10 -> Revisor : João Cleber
A6: =Contagem!A4&" : "&Contagem!F4 -> Empresa : Secretaria de Estado de Planejamento e Gestão de Mato Grosso | F6: ="Tipo de Contagem : "&Contagem!F6 -> Tipo de Contagem : Aplicação
B9: Deflatores aplicados a Itens Funcionais | E9: Quantidade | F9: PF IFPUG | G9: Deflator | H9: Contrib. Fixa | I9: PF Local da FS | J9: % LOCAL
B10: =""&Deflatores!B4 -> Inclusão | D10: =""&Deflatores!G4 -> I | E10: =IF(D10="","",COUNTIF(#REF!,D10)) -> #REF! | F10: =SUMIF(#REF!,Deflatores!G4,#REF!) -> #N/A | G10: =IF(ISBLANK(Deflatores!H4),"",Deflatores!H4) -> 1 | H10: =IF(ISBLANK(Deflatores!I4),"",Deflatores!I4) | I10: =IF(F10=0,Deflatores!K4,F10*G10) -> #N/A | J10: =IF($L$11<>0,I10/$L$11,"") -> #REF! | L10: PF Local da FS
B11: =""&Deflatores!B5 -> Alteração (sem conhecimento do Fator de Impacto) | D11: =""&Deflatores!G5 -> A | E11: =IF(D11="","",COUNTIF(#REF!,D11)) -> #REF! | F11: =SUMIF(#REF!,Deflatores!G5,#REF!) -> #N/A | G11: =IF(ISBLANK(Deflatores!H5),"",Deflatores!H5) -> 0.5 | H11: =IF(ISBLANK(Deflatores!I5),"",Deflatores!I5) | I11: =IF(F11=0,Deflatores!K5,F11*G11) -> #N/A | J11: =IF($L$11<>0,I11/$L$11,"") -> #REF! | L11: =Contagem!Q6 -> #REF!
B12: =""&Deflatores!B6 -> Exclusão | D12: =""&Deflatores!G6 -> E | E12: =IF(D12="","",COUNTIF(#REF!,D12)) -> #REF! | F12: =SUMIF(#REF!,Deflatores!G6,#REF!) -> #N/A | G12: =IF(ISBLANK(Deflatores!H6),"",Deflatores!H6) -> 0.4 | H12: =IF(ISBLANK(Deflatores!I6),"",Deflatores!I6) | I12: =IF(F12=0,Deflatores!K6,F12*G12) -> #N/A | J12: =IF($L$11<>0,I12/$L$11,"") -> #REF!
B13: =""&Deflatores!B7 -> Alteração (50%) de função desenvolvida ou já alterada pela empresa atual | D13: =""&Deflatores!G7 -> A50 | E13: =IF(D13="","",COUNTIF(#REF!,D13)) -> #REF! | F13: =SUMIF(#REF!,Deflatores!G7,#REF!) -> #N/A | G13: =IF(ISBLANK(Deflatores!H7),"",Deflatores!H7) -> 0.5 | H13: =IF(ISBLANK(Deflatores!I7),"",Deflatores!I7) | I13: =Deflatores!K7 -> #N/A | J13: =IF($L$11<>0,I13/$L$11,"") -> #REF! | L13: Total IFPUG
B14: =""&Deflatores!B8 -> Alteração (75%) de função não desenv. e ainda não alterada pela empresa atual | D14: =""&Deflatores!G8 -> A75 | E14: =IF(D14="","",COUNTIF(#REF!,D14)) -> #REF! | F14: =SUMIF(#REF!,Deflatores!G8,#REF!) -> #N/A | G14: =IF(ISBLANK(Deflatores!H8),"",Deflatores!H8) -> 0.75 | H14: =IF(ISBLANK(Deflatores!I8),"",Deflatores!I8) | I14: =Deflatores!K8 -> #N/A | J14: =IF($L$11<>0,I14/$L$11,"") -> #REF! | L14: =Contagem!Q4 -> #REF!
B15: =""&Deflatores!B9 -> Alteração (75%+15%): o mesmo acima + redocumentar a função | D15: =""&Deflatores!G9 -> A90 | E15: =IF(D15="","",COUNTIF(#REF!,D15)) -> #REF! | F15: =SUMIF(#REF!,Deflatores!G9,#REF!) -> #N/A | G15: =IF(ISBLANK(Deflatores!H9),"",Deflatores!H9) -> 0.9 | H15: =IF(ISBLANK(Deflatores!I9),"",Deflatores!I9) | I15: =Deflatores!K9 -> #N/A | J15: =IF($L$11<>0,I15/$L$11,"") -> #REF!
B16: =""&Deflatores!B10 -> Migração de Dados | D16: =""&Deflatores!G10 -> PMD | E16: =IF(D16="","",COUNTIF(#REF!,D16)) -> #REF! | F16: =SUMIF(#REF!,Deflatores!G10,#REF!) -> #N/A | G16: =IF(ISBLANK(Deflatores!H10),"",Deflatores!H10) -> 1 | H16: =IF(ISBLANK(Deflatores!I10),"",Deflatores!I10) | I16: =Deflatores!K10 -> #N/A | J16: =IF($L$11<>0,I16/$L$11,"") -> #REF!
